Workbook

Sheet STD SAP
A1: AHP 2012 Lama | K1: AHP 2012 REV | V1: 2015 REV
A2: # | B2: Age | C2: Average Body Weight (KG) | D2: Mortality (%) | E2: Vitality (%) | F2: Feed Convertion Ratio | G2: EEF / IP | H2: Feed Cons Daily | I2: Feed Cons Cumulative | K2: # | L2: Age | M2: Average Body Weight (KG) | N2: Mortality (%) | O2: Vitality (%) | P2: Feed Convertion Ratio | Q2: EEF / IP | R2: Feed Cons Daily | S2: Feed Cons Cumulative | T2: DIFF | V2: # | W2: Age | X2: Average Body Weight (KG) | Y2: Mortality (%) | Z2: Vitality (%) | AA2: Feed Convertion Ratio | AB2: EEF / IP | AC2: Feed Cons Daily | AD2: Feed Cons Cumulative
A3: 1 | B3: 0 | C3: 0.03 | D3: 0 | E3: 0 | F3: 0 | G3: 0 | H3: 0 | I3: 0 | K3: 1 | L3: 0 | M3: 0.03 | N3: 0 | P3: 0 | R3: 0 | S3: 0 | T3: {=_xlfn._xlws.FILTER(B3:B5000-L3:L5000,K3:K5000<>"")} -> 0 | V3: 1 | W3: 0 | X3: 0.042 | Y3: 0.093 | Z3: 0 | AA3: 0 | AB3: 0 | AC3: 0 | AD3: 0
A4: 2 | B4: 0 | C4: 0.031 | D4: 0.01 | E4: 0 | F4: 0.012 | G4: 0 | H4: 0 | I4: 0.001 | K4: 2 | L4: 0 | M4: 0.031 | N4: 0.008 | P4: 0.012 | R4: 0.001 | S4: 0.001 | T4: 0 | V4: 2 | W4: 0 | X4: 0.043 | Y4: 0.101 | Z4: 0 | AA4: 0.017 | AB4: 0 | AC4: 0.001 | AD4: 0.001
A5: 3 | B5: 0 | C5: 0.032 | D5: 0.02 | E5: 0 | F5: 0.024 | G5: 0 | H5: 0 | I5: 0.002 | K5: 3 | L5: 0 | M5: 0.032 | N5: 0.016 | P5: 0.024 | R5: 0.001 | S5: 0.001 | T5: 0 | V5: 3 | W5: 0 | X5: 0.044 | Y5: 0.109 | Z5: 0 | AA5: 0.033 | AB5: 0 | AC5: 0.002 | AD5: 0.002
A6: 4 | B6: 0 | C6: 0.033 | D6: 0.02 | E6: 0 | F6: 0.037 | G6: 0 | H6: 0 | I6: 0.002 | K6: 4 | L6: 0 | M6: 0.033 | N6: 0.023 | P6: 0.037 | R6: 0.002 | S6: 0.002 | T6: 0 | V6: 4 | W6: 0 | X6: 0.045 | Y6: 0.117 | Z6: 0 | AA6: 0.05 | AB6: 0 | AC6: 0.003 | AD6: 0.003
A7: 5 | B7: 0 | C7: 0.034 | D7: 0.03 | E7: 0 | F7: 0.049 | G7: 0 | H7: 0 | I7: 0.003 | K7: 5 | L7: 0 | M7: 0.034 | N7: 0.031 | P7: 0.049 | R7: 0.002 | S7: 0.002 | T7: 0 | V7: 5 | W7: 0 | X7: 0.046 | Y7: 0.124 | Z7: 0 | AA7: 0.066 | AB7: 0 | AC7: 0.004 | AD7: 0.004
A8: 6 | B8: 0 | C8: 0.035 | D8: 0.04 | E8: 0 | F8: 0.061 | G8: 0 | H8: 0 | I8: 0.004 | K8: 6 | L8: 0 | M8: 0.035 | N8: 0.039 | P8: 0.061 | R8: 0.003 | S8: 0.003 | T8: 0 | V8: 6 | W8: 0 | X8: 0.047 | Y8: 0.132 | Z8: 0 | AA8: 0.083 | AB8: 0 | AC8: 0.005 | AD8: 0.005
A9: 7 | B9: 0 | C9: 0.036 | D9: 0.05 | E9: 0 | F9: 0.073 | G9: 0 | H9: 0 | I9: 0.004 | K9: 7 | L9: 0 | M9: 0.036 | N9: 0.047 | P9: 0.073 | R9: 0.004 | S9: 0.004 | T9: 0 | V9: 7 | W9: 0 | X9: 0.048 | Y9: 0.14 | Z9: 0 | AA9: 0.099 | AB9: 0 | AC9: 0.006 | AD9: 0.006
A10: 8 | B10: 0 | C10: 0.037 | D10: 0.05 | E10: 0 | F10: 0.086 | G10: 0 | H10: 0 | I10: 0.005 | K10: 8 | L10: 0 | M10: 0.037 | N10: 0.054 | P10: 0.086 | R10: 0.004 | S10: 0.004 | T10: 0 | V10: 8 | W10: 0 | X10: 0.049 | Y10: 0.15 | Z10: 0 | AA10: 0.116 | AB10: 0 | AC10: 0.007 | AD10: 0.007
A11: 9 | B11: 0 | C11: 0.038 | D11: 0.06 | E11: 0 | F11: 0.098 | G11: 0 | H11: 0 | I11: 0.005 | K11: 9 | L11: 0 | M11: 0.038 | N11: 0.062 | P11: 0.098 | R11: 0.005 | S11: 0.005 | T11: 0 | V11: 9 | W11: 0 | X11: 0.05 | Y11: 0.16 | Z11: 0 | AA11: 0.133 | AB11: 0 | AC11: 0.007 | AD11: 0.007
A12: 10 | B12: 0 | C12: 0.039 | D12: 0.07 | E12: 0 | F12: 0.11 | G12: 0 | H12: 0 | I12: 0.006 | K12: 10 | L12: 0 | M12: 0.039 | N12: 0.07 | P12: 0.11 | R12: 0.005 | S12: 0.005 | T12: 0 | V12: 10 | W12: 0 | X12: 0.051 | Y12: 0.17 | Z12: 0 | AA12: 0.149 | AB12: 0 | AC12: 0.008 | AD12: 0.008
A13: 11 | B13: 0 | C13: 0.04 | D13: 0.08 | E13: 0 | F13: 0.122 | G13: 0 | H13: 0 | I13: 0.007 | K13: 11 | L13: 0 | M13: 0.04 | N13: 0.078 | P13: 0.122 | R13: 0.006 | S13: 0.006 | T13: 0 | V13: 11 | W13: 0 | X13: 0.052 | Y13: 0.18 | Z13: 0 | AA13: 0.166 | AB13: 0 | AC13: 0.009 | AD13: 0.009
A14: 12 | B14: 0 | C14: 0.041 | D14: 0.09 | E14: 0 | F14: 0.134 | G14: 0 | H14: 0 | I14: 0.007 | K14: 12 | L14: 0 | M14: 0.041 | N14: 0.086 | P14: 0.134 | R14: 0.007 | S14: 0.007 | T14: 0 | V14: 12 | W14: 0 | X14: 0.053 | Y14: 0.19 | Z14: 0 | AA14: 0.182 | AB14: 0 | AC14: 0.01 | AD14: 0.01
A15: 13 | B15: 0 | C15: 0.042 | D15: 0.09 | E15: 0 | F15: 0.147 | G15: 0 | H15: 0 | I15: 0.008 | K15: 13 | L15: 0 | M15: 0.042 | N15: 0.093 | P15: 0.147 | R15: 0.007 | S15: 0.007 | T15: 0 | V15: 13 | W15: 0 | X15: 0.054 | Y15: 0.2 | Z15: 0 | AA15: 0.199 | AB15: 0 | AC15: 0.011 | AD15: 0.011
... A3282: 3280 | B3282: 50 | C3282: 3.309 | D3282: 6.14 | E3282: 0 | F3282: 1.94 | G3282: 0 | H3282: 0.193 | I3282: 6.594 | K3282: 3280 | L3282: 50 | M3282: 3.309 | N3282: 6.266 | P3282: 1.943 | R3282: 0.195 | S3282: 6.428 | T3282: 0 | V3282: 3280 | W3282: 46 | X3282: 3.321 | Y3282: 6.28 | Z3282: 0 | AA3282: 1.779 | AB3282: 0 | AC3282: 0.231 | AD3282: 5.909
V3283: 3281 | W3283: 47 | X3283: 3.322 | Y3283: 6.28 | Z3283: 0 | AA3283: 1.779 | AB3283: 0 | AC3283: 0.231 | AD3283: 5.911
V3284: 3282 | W3284: 47 | X3284: 3.323 | Y3284: 6.28 | Z3284: 0 | AA3284: 1.779 | AB3284: 0 | AC3284: 0.231 | AD3284: 5.914
V3285: 3283 | W3285: 47 | X3285: 3.324 | Y3285: 6.28 | Z3285: 0 | AA3285: 1.779 | AB3285: 0 | AC3285: 0.231 | AD3285: 5.916
V3286: 3284 | W3286: 47 | X3286: 3.325 | Y3286: 6.28 | Z3286: 0 | AA3286: 1.78 | AB3286: 0 | AC3286: 0.231 | AD3286: 5.919
V3287: 3285 | W3287: 47 | X3287: 3.326 | Y3287: 6.28 | Z3287: 0 | AA3287: 1.78 | AB3287: 0 | AC3287: 0.231 | AD3287: 5.921
V3288: 3286 | W3288: 47 | X3288: 3.327 | Y3288: 6.28 | Z3288: 0 | AA3288: 1.78 | AB3288: 0 | AC3288: 0.231 | AD3288: 5.924
V3289: 3287 | W3289: 47 | X3289: 3.328 | Y3289: 6.28 | Z3289: 0 | AA3289: 1.78 | AB3289: 0 | AC3289: 0.231 | AD3289: 5.926
V3290: 3288 | W3290: 47 | X3290: 3.329 | Y3290: 6.28 | Z3290: 0 | AA3290: 1.781 | AB3290: 0 | AC3290: 0.231 | AD3290: 5.929
V3291: 3289 | W3291: 47 | X3291: 3.33 | Y3291: 6.28 | Z3291: 0 | AA3291: 1.781 | AB3291: 0 | AC3291: 0.231 | AD3291: 5.931
V3292: 3290 | W3292: 47 | X3292: 3.331 | Y3292: 6.28 | Z3292: 0 | AA3292: 1.781 | AB3292: 0 | AC3292: 0.231 | AD3292: 5.934
V3293: 3291 | W3293: 47 | X3293: 3.332 | Y3293: 6.28 | Z3293: 0 | AA3293: 1.781 | AB3293: 0 | AC3293: 0.231 | AD3293: 5.936
V3294: 3292 | W3294: 47 | X3294: 3.333 | Y3294: 6.28 | Z3294: 0 | AA3294: 1.782 | AB3294: 0 | AC3294: 0.231 | AD3294: 5.939
... V3733: 3731 | W3733: 51 | X3733: 3.772 | Y3733: 7 | Z3733: 0 | AA3733: 1.88 | AB3733: 0 | AC3733: 0.24 | AD3733: 7.092

Sheet STD COBB
A1: 2018 | K1: 2015 | AA1: 2012 | AL1: {=_xlfn.UNIQUE(AA:AA)} -> 2012
A2: Age | B2: Weight | C2: Daily | D2: Average | E2: Cumulative Feed | F2: Daily Feed | G2: Cumulative Feed | H2: Populasi | K2: Age | L2: Weight | M2: Daily | N2: Average | O2: Cumulative Feed | P2: Daily Feed | Q2: Cumulative Feed | R2: Populasi | S2: ZAK | T2: {=_xlfn.UNIQUE('STD SAP'!W:W)} -> 0 | AA2: STANDARD FCR EEF & COST OF BROILER | AL2: STANDARD FCR EEF & COST OF BROILER
A3: days | B3: for Age (g) | C3: Gain (g) | D3: Daily Gain (g) | E3: Conversion | F3: Consumption (g) | G3: Consumption (g) | H3: ='Simulasi IBOCS'!C4 -> 17372 | K3: days | L3: for Age (g) | M3: Gain (g) | N3: Daily Gain (g) | O3: Conversion | P3: Consumption (g) | Q3: Consumption (g) | R3: 16656 | T3: Age | AA3: AGE (Days) | AB3: ABW | AC3: Mort (%) | AD3: FCR | AE3: Cum FI | AF3: EEF | AG3: ADG | AH3: D FI | AL3: AGE (Days) | AM3: BW | AN3: CUM FI | AO3: D FI
B4: 2 | C4: 3 | D4: 4 | E4: 5 | F4: 6 | G4: 7 | K4: 0 | L4: 42 | M4: 0 | T4: 0 | U4: =_xlfn.XLOOKUP($T4,'STD SAP'!$W:$W,'STD SAP'!X:X)*1000-L4 -> 0 | V4: =_xlfn.XLOOKUP($T4,'STD SAP'!$W:$W,'STD SAP'!AA:AA)-O4 -> 0 | W4: {=_xlfn.LET( _xlpm.bw,AM4:AM55, _xlpm.fcr,AO4:AO55, _xlpm.minBW,MIN(_xlpm.bw), _xlpm.maxBW,MAX(_xlpm.bw), _xlpm.x,_xlfn.SEQUENCE(_xlpm.maxBW-_xlpm.minBW+1,1,_xlpm.minBW,1), _xlpm.bw_bawah,_xlfn.XLOOKUP(_xlpm.x,_xlpm.bw,_xlpm.bw,"",-1), _xlpm.bw_atas,_xlfn.XLOOKUP(_xlpm.x,_xlpm.bw,_xlpm.bw,"",1), _xlpm.fcr_bawah,_xlfn.XLOOKUP(_xlpm.x,_xlpm.bw,_xlpm.fcr,"",-1), _xlpm.fcr_atas,_xlfn.XLOOKUP(_xlpm.x,_xlpm.bw,_xlpm.fcr,"",1), _xlpm.hasil, IF( _xlpm.bw_bawah=_xlpm.bw_atas, _xlpm.fcr_bawah, _xlpm.fcr_bawah + (_xlpm.x-_xlpm.bw_bawah)*(_xlpm.fcr_atas-_xlpm.fcr_bawah)/(_xlpm.bw_atas-_xlpm.bw_bawah) ), _xlfn.HSTACK(_xlpm.x,ROUND(_xlpm.hasil,3)) )} -> 30 | X4: 0 | Y4: =ROUND(X4/1000,3) -> 0 | AA4: 0 | AB4: 0.03 | AC4: 0 | AD4: 0 | AE4: 0 | AF4: 0 | AG4: 0 | AH4: 0 | AI4: =AB4*1000 -> 30 | AJ4: =ROUND(W4/1000,3) -> 0.03 | AL4: 0 | AM4: =_xlfn.XLOOKUP(AL4,AA:AA,AB:AB)*1000 -> 30 | AN4: =_xlfn.SINGLE(_xlfn.XLOOKUP(AL4,AA:AA,AE:AE))*1000 -> 0 | AP4: =ROUND(X4/1000,3) -> 0 | AQ4: =Y4 -> 0
A5: 0 | B5: 42 | C5: 0 | H5: =$H$3*F5/1000 -> 0 | K5: 1 | L5: 56 | M5: 14 | O5: 0.232 | P5: 13 | Q5: 13 | R5: =$R$3*P5/1000 -> 216.528 | S5: =CEILING(R5/50,0.5) -> 4.5 | T5: 1 | U5: =_xlfn.XLOOKUP($T5,'STD SAP'!$W:$W,'STD SAP'!X:X)*1000-L5 -> 0 | V5: =_xlfn.XLOOKUP($T5,'STD SAP'!$W:$W,'STD SAP'!AA:AA)-O5 -> 0 | W5: 31 | X5: 0.606 | Y5: =ROUND(X5/1000,3) -> 0.001 | AA5: 1 | AB5: 0.048 | AC5: 0.14 | AD5: 0.22 | AE5: 0.0109 | AH5: =AE5-AE4 -> 0.0109 | AI5: =AB5*1000 -> 48 | AJ5: =ROUND(W5/1000,3) -> 0.031 | AL5: 1 | AM5: =_xlfn.SINGLE(_xlfn.XLOOKUP(AL5,AA:AA,AB:AB))*1000 -> 48 | AN5: =_xlfn.SINGLE(_xlfn.XLOOKUP(AL5,AA:AA,AE:AE))*1000 -> 10.9 | AO5: =+AN5-AN4 -> 10.9 | AP5: =ROUND(X5/1000,3) -> 0.001
A6: 1 | B6: 63 | C6: 14 | F6: 12 | H6: =$H$3*F6/1000 -> 208.464 | K6: 2 | L6: 72 | M6: 16 | O6: 0.417 | P6: 17 | Q6: 30 | R6: =$R$3*P6/1000 -> 283.152 | S6: =CEILING(R6/50,0.5) -> 6 | T6: 2 | U6: =_xlfn.XLOOKUP($T6,'STD SAP'!$W:$W,'STD SAP'!X:X)*1000-L6 -> 0 | V6: =_xlfn.XLOOKUP($T6,'STD SAP'!$W:$W,'STD SAP'!AA:AA)-O6 -> 0 | W6: 32 | X6: 1.211 | Y6: =ROUND(X6/1000,3) -> 0.001 | AA6: 2 | AB6: 0.062 | AC6: 0.28 | AD6: 0.4 | AE6: 0.02515 | AH6: =AE6-AE5 -> 0.01425 | AI6: =AB6*1000 -> 62 | AJ6: =ROUND(W6/1000,3) -> 0.032 | AL6: 2 | AM6: =_xlfn.SINGLE(_xlfn.XLOOKUP(AL6,AA:AA,AB:AB))*1000 -> 62 | AN6: =_xlfn.SINGLE(_xlfn.XLOOKUP(AL6,AA:AA,AE:AE))*1000 -> 25.15 | AO6: =+AN6-AN5 -> 14.25 | AP6: =ROUND(X6/1000,3) -> 0.001
A7: 2 | B7: 74 | C7: 16 | F7: 15 | H7: =$H$3*F7/1000 -> 260.58 | K7: 3 | L7: 89 | M7: 17 | O7: 0.573 | P7: 21 | Q7: 51 | R7: =$R$3*P7/1000 -> 349.776 | S7: =CEILING(R7/50,0.5) -> 7 | T7: 3 | U7: =_xlfn.XLOOKUP($T7,'STD SAP'!$W:$W,'STD SAP'!X:X)*1000-L7 -> 0 | V7: =_xlfn.XLOOKUP($T7,'STD SAP'!$W:$W,'STD SAP'!AA:AA)-O7 -> 0 | W7: 33 | X7: 1.817 | Y7: =ROUND(X7/1000,3) -> 0.002 | AA7: 3 | AB7: 0.077 | AC7: 0.42 | AD7: 0.54 | AE7: 0.04275 | AH7: =AE7-AE6 -> 0.0176 | AI7: =AB7*1000 -> 77 | AJ7: =ROUND(W7/1000,3) -> 0.033 | AL7: 3 | AM7: =_xlfn.SINGLE(_xlfn.XLOOKUP(AL7,AA:AA,AB:AB))*1000 -> 77 | AN7: =_xlfn.SINGLE(_xlfn.XLOOKUP(AL7,AA:AA,AE:AE))*1000 -> 42.75 | AO7: =+AN7-AN6 -> 17.6 | AP7: =ROUND(X7/1000,3) -> 0.002
A8: 3 | B8: 90 | C8: 17 | F8: 19 | H8: =$H$3*F8/1000 -> 330.068 | K8: 4 | L8: 109 | M8: 20 | O8: 0.679 | P8: 23 | Q8: 74 | R8: =$R$3*P8/1000 -> 383.088 | S8: =CEILING(R8/50,0.5) -> 8 | T8: 4 | U8: =_xlfn.XLOOKUP($T8,'STD SAP'!$W:$W,'STD SAP'!X:X)*1000-L8 -> 0 | V8: =_xlfn.XLOOKUP($T8,'STD SAP'!$W:$W,'STD SAP'!AA:AA)-O8 -> 0 | W8: 34 | X8: 2.422 | Y8: =ROUND(X8/1000,3) -> 0.002 | AA8: 4 | AB8: 0.094 | AC8: 0.56 | AD8: 0.64 | AE8: 0.06204 | AH8: =AE8-AE7 -> 0.01929 | AI8: =AB8*1000 -> 94 | AJ8: =ROUND(W8/1000,3) -> 0.034 | AL8: 4 | AM8: =_xlfn.SINGLE(_xlfn.XLOOKUP(AL8,AA:AA,AB:AB))*1000 -> 94 | AN8: =_xlfn.SINGLE(_xlfn.XLOOKUP(AL8,AA:AA,AE:AE))*1000 -> 62.04 | AO8: =+AN8-AN7 -> 19.29 | AP8: =ROUND(X8/1000,3) -> 0.002
A9: 4 | B9: 109 | C9: 20 | F9: 22 | H9: =$H$3*F9/1000 -> 382.184 | K9: 5 | L9: 131 | M9: 22 | O9: 0.773 | P9: 27 | Q9: 101 | R9: =$R$3*P9/1000 -> 449.712 | S9: =CEILING(R9/50,0.5) -> 9 | T9: 5 | U9: =_xlfn.XLOOKUP($T9,'STD SAP'!$W:$W,'STD SAP'!X:X)*1000-L9 -> 0 | V9: =_xlfn.XLOOKUP($T9,'STD SAP'!$W:$W,'STD SAP'!AA:AA)-O9 -> 0 | W9: 35 | X9: 3.028 | Y9: =ROUND(X9/1000,3) -> 0.003 | AA9: 5 | AB9: 0.113 | AC9: 0.7 | AD9: 0.73 | AE9: 0.08467 | AH9: =AE9-AE8 -> 0.02263 | AI9: =AB9*1000 -> 113 | AJ9: =ROUND(W9/1000,3) -> 0.035 | AL9: 5 | AM9: =_xlfn.SINGLE(_xlfn.XLOOKUP(AL9,AA:AA,AB:AB))*1000 -> 113 | AN9: =_xlfn.SINGLE(_xlfn.XLOOKUP(AL9,AA:AA,AE:AE))*1000 -> 84.67 | AO9: =+AN9-AN8 -> 22.63 | AP9: =ROUND(X9/1000,3) -> 0.003
A10: 5 | B10: 134 | C10: 22 | F10: 25 | H10: =$H$3*F10/1000 -> 434.3 | K10: 6 | L10: 157 | M10: 26 | O10: 0.841 | P10: 31 | Q10: 132 | R10: =$R$3*P10/1000 -> 516.336 | S10: =CEILING(R10/50,0.5) -> 10.5 | T10: 6 | U10: =_xlfn.XLOOKUP($T10,'STD SAP'!$W:$W,'STD SAP'!X:X)*1000-L10 -> 0 | V10: =_xlfn.XLOOKUP($T10,'STD SAP'!$W:$W,'STD SAP'!AA:AA)-O10 -> 0 | W10: 36 | X10: 3.633 | Y10: =ROUND(X10/1000,3) -> 0.004 | AA10: 6 | AB10: 0.136 | AC10: 0.84 | AD10: 0.8 | AE10: 0.11066 | AH10: =AE10-AE9 -> 0.02599 | AI10: =AB10*1000 -> 136 | AJ10: =ROUND(W10/1000,3) -> 0.036 | AL10: 6 | AM10: =_xlfn.SINGLE(_xlfn.XLOOKUP(AL10,AA:AA,AB:AB))*1000 -> 136 | AN10: =_xlfn.SINGLE(_xlfn.XLOOKUP(AL10,AA:AA,AE:AE))*1000 -> 110.66 | AO10: =+AN10-AN9 -> 25.99 | AP10: =ROUND(X10/1000,3) -> 0.004
A11: 6 | B11: 163 | C11: 26 | F11: 30 | H11: =$H$3*F11/1000 -> 521.16 | K11: 7 | L11: 185 | M11: 28 | N11: 26.4 | O11: 0.902 | P11: 35 | Q11: 167 | R11: =$R$3*P11/1000 -> 582.96 | S11: =CEILING(R11/50,0.5) -> 12 | T11: 7 | U11: =_xlfn.XLOOKUP($T11,'STD SAP'!$W:$W,'STD SAP'!X:X)*1000-L11 -> 0 | V11: =_xlfn.XLOOKUP($T11,'STD SAP'!$W:$W,'STD SAP'!AA:AA)-O11 -> 0 | W11: 37 | X11: 4.239 | Y11: =ROUND(X11/1000,3) -> 0.004 | AA11: 7 | AB11: 0.16 | AC11: 1 | AD11: 0.856 | AE11: 0.14 | AF11: 271 | AG11: 23 | AH11: =AE11-AE10 -> 0.02934 | AI11: =AB11*1000 -> 160 | AJ11: =ROUND(W11/1000,3) -> 0.037 | AL11: 7 | AM11: =_xlfn.SINGLE(_xlfn.XLOOKUP(AL11,AA:AA,AB:AB))*1000 -> 160 | AN11: =_xlfn.SINGLE(_xlfn.XLOOKUP(AL11,AA:AA,AE:AE))*1000 -> 140 | AO11: =+AN11-AN10 -> 29.34 | AP11: =ROUND(X11/1000,3) -> 0.004
A12: 7 | B12: 193 | C12: 30 | D12: 28 | E12: 0.76 | F12: 33 | G12: 145 | H12: =$H$3*F12/1000 -> 573.276 | K12: 8 | L12: 215 | M12: 30 | N12: 26.9 | O12: 0.958 | P12: 39 | Q12: 206 | R12: =$R$3*P12/1000 -> 649.584 | S12: =CEILING(R12/50,0.5) -> 13 | T12: 8 | U12: =_xlfn.XLOOKUP($T12,'STD SAP'!$W:$W,'STD SAP'!X:X)*1000-L12 -> 0 | V12: =_xlfn.XLOOKUP($T12,'STD SAP'!$W:$W,'STD SAP'!AA:AA)-O12 -> 0 | W12: 38 | X12: 4.844 | Y12: =ROUND(X12/1000,3) -> 0.005 | AA12: 8 | AB12: 0.2 | AC12: 1.11 | AD12: 0.885 | AE12: 0.179 | AF12: 282 | AG12: 25 | AH12: =AE12-AE11 -> 0.039 | AI12: =AB12*1000 -> 200 | AJ12: =ROUND(W12/1000,3) -> 0.038 | AL12: 8 | AM12: =_xlfn.SINGLE(_xlfn.XLOOKUP(AL12,AA:AA,AB:AB))*1000 -> 200 | AN12: =_xlfn.SINGLE(_xlfn.XLOOKUP(AL12,AA:AA,AE:AE))*1000 -> 179 | AO12: =+AN12-AN11 -> 39 | AP12: =ROUND(X12/1000,3) -> 0.005
A13: 8 | B13: 228 | C13: 36 | D13: 29 | E13: 0.8 | F13: 37 | G13: 182 | H13: =$H$3*F13/1000 -> 642.764 | K13: 9 | L13: 247 | M13: 32 | N13: 27.4 | O13: 1.012 | P13: 44 | Q13: 250 | R13: =$R$3*P13/1000 -> 732.864 | S13: =CEILING(R13/50,0.5) -> 15 | T13: 9 | U13: =_xlfn.XLOOKUP($T13,'STD SAP'!$W:$W,'STD SAP'!X:X)*1000-L13 -> 0 | V13: =_xlfn.XLOOKUP($T13,'STD SAP'!$W:$W,'STD SAP'!AA:AA)-O13 -> 0 | W13: 39 | X13: 5.45 | Y13: =ROUND(X13/1000,3) -> 0.005 | AA13: 9 | AB13: 0.24 | AC13: 1.21 | AD13: 0.914 | AE13: 0.219 | AF13: 288 | AG13: 27 | AH13: =AE13-AE12 -> 0.04 | AI13: =AB13*1000 -> 240 | AJ13: =ROUND(W13/1000,3) -> 0.039 | AL13: 9 | AM13: =_xlfn.SINGLE(_xlfn.XLOOKUP(AL13,AA:AA,AB:AB))*1000 -> 240 | AN13: =_xlfn.SINGLE(_xlfn.XLOOKUP(AL13,AA:AA,AE:AE))*1000 -> 219 | AO13: =+AN13-AN12 -> 40 | AP13: =ROUND(X13/1000,3) -> 0.005
A14: 9 | B14: 269 | C14: 41 | D14: 30 | E14: 0.84 | F14: 43 | G14: 225 | H14: =$H$3*F14/1000 -> 746.996 | K14: 10 | L14: 283 | M14: 36 | N14: 28.3 | O14: 1.053 | P14: 48 | Q14: 298 | R14: =$R$3*P14/1000 -> 799.488 | S14: =CEILING(R14/50,0.5) -> 16 | T14: 10 | U14: =_xlfn.XLOOKUP($T14,'STD SAP'!$W:$W,'STD SAP'!X:X)*1000-L14 -> 0 | V14: =_xlfn.XLOOKUP($T14,'STD SAP'!$W:$W,'STD SAP'!AA:AA)-O14 -> 0 | W14: 40 | X14: 6.056 | Y14: =ROUND(X14/1000,3) -> 0.006 | AA14: 10 | AB14: 0.28 | AC14: 1.32 | AD14: 0.943 | AE14: 0.262 | AF14: 291 | AG14: 28 | AH14: =AE14-AE13 -> 0.043 | AI14: =AB14*1000 -> 280 | AJ14: =ROUND(W14/1000,3) -> 0.04 | AL14: 10 | AM14: =_xlfn.SINGLE(_xlfn.XLOOKUP(AL14,AA:AA,AB:AB))*1000 -> 280 | AN14: =_xlfn.SINGLE(_xlfn.XLOOKUP(AL14,AA:AA,AE:AE))*1000 -> 262 | AO14: =+AN14-AN13 -> 43 | AP14: =ROUND(X14/1000,3) -> 0.006
A15: 10 | B15: 313 | C15: 44 | D15: 31 | E15: 0.88 | F15: 50 | G15: 275 | H15: =$H$3*F15/1000 -> 868.6 | K15: 11 | L15: 321 | M15: 38 | N15: 29.2 | O15: 1.097 | P15: 54 | Q15: 352 | R15: =$R$3*P15/1000 -> 899.424 | S15: =CEILING(R15/50,0.5) -> 18 | T15: 11 | U15: =_xlfn.XLOOKUP($T15,'STD SAP'!$W:$W,'STD SAP'!X:X)*1000-L15 -> 0 | V15: =_xlfn.XLOOKUP($T15,'STD SAP'!$W:$W,'STD SAP'!AA:AA)-O15 -> 0 | W15: 41 | X15: 6.661 | Y15: =ROUND(X15/1000,3) -> 0.007 | AA15: 11 | AB15: 0.32 | AC15: 1.43 | AD15: 0.972 | AE15: 0.307 | AF15: 291 | AG15: 29 | AH15: =AE15-AE14 -> 0.045 | AI15: =AB15*1000 -> 320 | AJ15: =ROUND(W15/1000,3) -> 0.041 | AL15: 11 | AM15: =_xlfn.SINGLE(_xlfn.XLOOKUP(AL15,AA:AA,AB:AB))*1000 -> 320 | AN15: =_xlfn.SINGLE(_xlfn.XLOOKUP(AL15,AA:AA,AE:AE))*1000 -> 307 | AO15: =+AN15-AN14 -> 45 | AP15: =ROUND(X15/1000,3) -> 0.007
A16: 11 | B16: 362 | C16: 48 | D16: 33 | E16: 0.92 | F16: 57 | G16: 331 | H16: =$H$3*F16/1000 -> 990.204 | K16: 12 | L16: 364 | M16: 43 | N16: 30.3 | O16: 1.126 | P16: 58 | Q16: 410 | R16: =$R$3*P16/1000 -> 966.048 | S16: =CEILING(R16/50,0.5) -> 19.5 | T16: 12 | U16: =_xlfn.XLOOKUP($T16,'STD SAP'!$W:$W,'STD SAP'!X:X)*1000-L16 -> 0 | V16: =_xlfn.XLOOKUP($T16,'STD SAP'!$W:$W,'STD SAP'!AA:AA)-O16 -> 0 | W16: 42 | X16: 7.267 | Y16: =ROUND(X16/1000,3) -> 0.007 | AA16: 12 | AB16: 0.35 | AC16: 1.54 | AD16: 1.001 | AE16: 0.354 | AF16: 290 | AG16: 30 | AH16: =AE16-AE15 -> 0.047 | AI16: =AB16*1000 -> 350 | AJ16: =ROUND(W16/1000,3) -> 0.042 | AL16: 12 | AM16: =_xlfn.SINGLE(_xlfn.XLOOKUP(AL16,AA:AA,AB:AB))*1000 -> 350 | AN16: =_xlfn.SINGLE(_xlfn.XLOOKUP(AL16,AA:AA,AE:AE))*1000 -> 354 | AO16: =+AN16-AN15 -> 47 | AP16: =ROUND(X16/1000,3) -> 0.007
A17: 12 | B17: 414 | C17: 52 | D17: 34 | E17: 0.95 | F17: 64 | G17: 395 | H17: =$H$3*F17/1000 -> 1111.808 | K17: 13 | L17: 412 | M17: 48 | N17: 31.7 | O17: 1.15 | P17: 64 | Q17: 474 | R17: =$R$3*P17/1000 -> 1065.984 | S17: =CEILING(R17/50,0.5) -> 21.5 | T17: 13 | U17: =_xlfn.XLOOKUP($T17,'STD SAP'!$W:$W,'STD SAP'!X:X)*1000-L17 -> 0 | V17: =_xlfn.XLOOKUP($T17,'STD SAP'!$W:$W,'STD SAP'!AA:AA)-O17 -> 0 | W17: 43 | X17: 7.872 | Y17: =ROUND(X17/1000,3) -> 0.008 | AA17: 13 | AB17: 0.39 | AC17: 1.64 | AD17: 1.03 | AE17: 0.404 | AF17: 288 | AG17: 30 | AH17: =AE17-AE16 -> 0.05 | AI17: =AB17*1000 -> 390 | AJ17: =ROUND(W17/1000,3) -> 0.043 | AL17: 13 | AM17: =_xlfn.SINGLE(_xlfn.XLOOKUP(AL17,AA:AA,AB:AB))*1000 -> 390 | AN17: =_xlfn.SINGLE(_xlfn.XLOOKUP(AL17,AA:AA,AE:AE))*1000 -> 404 | AO17: =+AN17-AN16 -> 50 | AP17: =ROUND(X17/1000,3) -> 0.008
A18: 13 | B18: 469 | C18: 55 | D18: 36 | E18: 1 | F18: 72 | G18: 467 | H18: =$H$3*F18/1000 -> 1250.784 | K18: 14 | L18: 465 | M18: 53 | N18: 33.2 | O18: 1.165 | P18: 68 | Q18: 542 | R18: =$R$3*P18/1000 -> 1132.608 | S18: =CEILING(R18/50,0.5) -> 23 | T18: 14 | U18: =_xlfn.XLOOKUP($T18,'STD SAP'!$W:$W,'STD SAP'!X:X)*1000-L18 -> 0 | V18: =_xlfn.XLOOKUP($T18,'STD SAP'!$W:$W,'STD SAP'!AA:AA)-O18 -> 0 | W18: 44 | X18: 8.478 | Y18: =ROUND(X18/1000,3) -> 0.008 | AA18: 14 | AB18: 0.43 | AC18: 1.75 | AD18: 1.059 | AE18: 0.455 | AF18: 285 | AG18: 31 | AH18: =AE18-AE17 -> 0.051 | AI18: =AB18*1000 -> 430 | AJ18: =ROUND(W18/1000,3) -> 0.044 | AL18: 14 | AM18: =_xlfn.SINGLE(_xlfn.XLOOKUP(AL18,AA:AA,AB:AB))*1000 -> 430 | AN18: =_xlfn.SINGLE(_xlfn.XLOOKUP(AL18,AA:AA,AE:AE))*1000 -> 455 | AO18: =+AN18-AN17 -> 51 | AP18: =ROUND(X18/1000,3) -> 0.008
A19: 14 | B19: 528 | C19: 59 | D19: 38 | E19: 1.03 | F19: 74 | G19: 541 | H19: =$H$3*F19/1000 -> 1285.528 | K19: 15 | L19: 524 | M19: 59 | N19: 34.9 | O19: 1.177 | P19: 75 | Q19: 617 | R19: =$R$3*P19/1000 -> 1249.2 | S19: =CEILING(R19/50,0.5) -> 25 | T19: 15 | U19: =_xlfn.XLOOKUP($T19,'STD SAP'!$W:$W,'STD SAP'!X:X)*1000-L19 -> 0 | V19: =_xlfn.XLOOKUP($T19,'STD SAP'!$W:$W,'STD SAP'!AA:AA)-O19 -> 0 | W19: 45 | X19: 9.083 | Y19: =ROUND(X19/1000,3) -> 0.009 | AA19: 14 | AB19: 0.44 | AC19: 1.75 | AD19: 1.064 | AE19: 0.468 | AF19: 290 | AG19: 31 | AH19: =AE19-AE18 -> 0.013 | AI19: =AB19*1000 -> 440 | AJ19: =ROUND(W19/1000,3) -> 0.045 | AL19: 15 | AM19: =_xlfn.SINGLE(_xlfn.XLOOKUP(AL19,AA:AA,AB:AB))*1000 -> 490 | AN19: =_xlfn.SINGLE(_xlfn.XLOOKUP(AL19,AA:AA,AE:AE))*1000 -> 532 | AO19: =+AN19-AN18 -> 77 | AP19: =ROUND(X19/1000,3) -> 0.009
A20: 15 | B20: 589 | C20: 62 | D20: 39 | E20: 1.05 | F20: 78 | G20: 619 | H20: =$H$3*F20/1000 -> 1355.016 | K20: 16 | L20: 586 | M20: 62 | N20: 36.6 | O20: 1.191 | P20: 81 | Q20: 698 | R20: =$R$3*P20/1000 -> 1349.136 | S20: =CEILING(R20/50,0.5) -> 27 | T20: 16 | U20: =_xlfn.XLOOKUP($T20,'STD SAP'!$W:$W,'STD SAP'!X:X)*1000-L20 -> 0 | V20: =_xlfn.XLOOKUP($T20,'STD SAP'!$W:$W,'STD SAP'!AA:AA)-O20 -> 0 | W20: 46 | X20: 9.689 | Y20: =ROUND(X20/1000,3) -> 0.01 | AA20: 14 | AB20: 0.45 | AC20: 1.75 | AD20: 1.069 | AE20: 0.481 | AF20: 296 | AG20: 32 | AH20: =AE20-AE19 -> 0.013 | AI20: =AB20*1000 -> 450 | AJ20: =ROUND(W20/1000,3) -> 0.046 | AL20: 16 | AM20: =_xlfn.SINGLE(_xlfn.XLOOKUP(AL20,AA:AA,AB:AB))*1000 -> 550 | AN20: =_xlfn.SINGLE(_xlfn.XLOOKUP(AL20,AA:AA,AE:AE))*1000 -> 612 | AO20: =+AN20-AN19 -> 80 | AP20: =ROUND(X20/1000,3) -> 0.01
A21: 16 | B21: 654 | C21: 65 | D21: 41 | E21: 1.08 | F21: 85 | G21: 704 | H21: =$H$3*F21/1000 -> 1476.62 | K21: 17 | L21: 651 | M21: 65 | N21: 38.3 | O21: 1.206 | P21: 87 | Q21: 785 | R21: =$R$3*P21/1000 -> 1449.072 | S21: =CEILING(R21/50,0.5) -> 29 | T21: 17 | U21: =_xlfn.XLOOKUP($T21,'STD SAP'!$W:$W,'STD SAP'!X:X)*1000-L21 -> 0 | V21: =_xlfn.XLOOKUP($T21,'STD SAP'!$W:$W,'STD SAP'!AA:AA)-O21 -> 0 | W21: 47 | X21: 10.294 | Y21: =ROUND(X21/1000,3) -> 0.01 | AA21: 14 | AB21: 0.46 | AC21: 1.75 | AD21: 1.073 | AE21: 0.494 | AF21: 301 | AG21: 33 | AH21: =AE21-AE20 -> 0.013 | AI21: =AB21*1000 -> 460 | AJ21: =ROUND(W21/1000,3) -> 0.047 | AL21: 17 | AM21: =_xlfn.SINGLE(_xlfn.XLOOKUP(AL21,AA:AA,AB:AB))*1000 -> 610 | AN21: =_xlfn.SINGLE(_xlfn.XLOOKUP(AL21,AA:AA,AE:AE))*1000 -> 695 | AO21: =+AN21-AN20 -> 83 | AP21: =ROUND(X21/1000,3) -> 0.01
A22: 17 | B22: 722 | C22: 68 | D22: 42 | E22: 1.1 | F22: 91 | G22: 795 | H22: =$H$3*F22/1000 -> 1580.852 | K22: 18 | L22: 719 | M22: 68 | N22: 39.9 | O22: 1.221 | P22: 93 | Q22: 878 | R22: =$R$3*P22/1000 -> 1549.008 | S22: =CEILING(R22/50,0.5) -> 31 | T22: 18 | U22: =_xlfn.XLOOKUP($T22,'STD SAP'!$W:$W,'STD SAP'!X:X)*1000-L22 -> 0 | V22: =_xlfn.XLOOKUP($T22,'STD SAP'!$W:$W,'STD SAP'!AA:AA)-O22 -> 0 | W22: 48 | X22: 10.9 | Y22: =ROUND(X22/1000,3) -> 0.011 | AA22: 14 | AB22: 0.47 | AC22: 1.75 | AD22: 1.078 | AE22: 0.507 | AF22: 306 | AG22: 34 | AH22: =AE22-AE21 -> 0.013 | AI22: =AB22*1000 -> 470 | AJ22: =ROUND(W22/1000,3) -> 0.048 | AL22: 18 | AM22: =_xlfn.SINGLE(_xlfn.XLOOKUP(AL22,AA:AA,AB:AB))*1000 -> 670 | AN22: =_xlfn.SINGLE(_xlfn.XLOOKUP(AL22,AA:AA,AE:AE))*1000 -> 782 | AO22: =+AN22-AN21 -> 87 | AP22: =ROUND(X22/1000,3) -> 0.011
A23: 18 | B23: 792 | C23: 70 | D23: 44 | E23: 1.13 | F23: 103 | G23: 898 | H23: =$H$3*F23/1000 -> 1789.316 | K23: 19 | L23: 790 | M23: 71 | N23: 41.6 | O23: 1.235 | P23: 98 | Q23: 976 | R23: =$R$3*P23/1000 -> 1632.288 | S23: =CEILING(R23/50,0.5) -> 33 | T23: 19 | U23: =_xlfn.XLOOKUP($T23,'STD SAP'!$W:$W,'STD SAP'!X:X)*1000-L23 -> 0 | V23: =_xlfn.XLOOKUP($T23,'STD SAP'!$W:$W,'STD SAP'!AA:AA)-O23 -> 0 | W23: 49 | X23: 11.139 | Y23: =ROUND(X23/1000,3) -> 0.011 | AA23: 14 | AB23: 0.48 | AC23: 1.75 | AD23: 1.083 | AE23: 0.52 | AF23: 311 | AG23: 34 | AH23: =AE23-AE22 -> 0.013 | AI23: =AB23*1000 -> 480 | AJ23: =ROUND(W23/1000,3) -> 0.049 | AL23: 19 | AM23: =_xlfn.SINGLE(_xlfn.XLOOKUP(AL23,AA:AA,AB:AB))*1000 -> 730 | AN23: =_xlfn.SINGLE(_xlfn.XLOOKUP(AL23,AA:AA,AE:AE))*1000 -> 872 | AO23: =+AN23-AN22 -> 90 | AP23: =ROUND(X23/1000,3) -> 0.011
... A54: 49 | B54: 3617 | C54: 93 | D54: 74 | E54: 1.76 | F54: 241 | G54: 6349 | H54: =$H$3*F54/1000 -> 4186.652 | K54: 50 | L54: 3596 | M54: 90 | N54: 71.9 | O54: 1.84 | P54: 237 | Q54: 6616 | R54: =$R$3*P54/1000 -> 3947.472 | S54: =CEILING(R54/50,0.5) -> 79 | T54: 50 | U54: =_xlfn.XLOOKUP($T54,'STD SAP'!$W:$W,'STD SAP'!X:X)*1000-L54 -> 0 | V54: =_xlfn.XLOOKUP($T54,'STD SAP'!$W:$W,'STD SAP'!AA:AA)-O54 -> 0 | W54: 80 | X54: 17.898 | Y54: =ROUND(X54/1000,3) -> 0.018 | AA54: 20 | AB54: 0.79 | AC54: 2.39 | AD54: 1.237 | AE54: 0.977 | AF54: 312 | AG54: 40 | AH54: =AE54-AE53 -> 0.011 | AI54: =AB54*1000 -> 790 | AJ54: =ROUND(W54/1000,3) -> 0.08 | AL54: 50 | AM54: =_xlfn.SINGLE(_xlfn.XLOOKUP(AL54,AA:AA,AB:AB))*1000 -> 3240 | AN54: =_xlfn.SINGLE(_xlfn.XLOOKUP(AL54,AA:AA,AE:AE))*1000 -> 6236 | AO54: =+AN54-AN53 -> 193 | AP54: =ROUND(X54/1000,3) -> 0.018
A55: 50 | B55: 3707 | C55: 91 | D55: 74 | E55: 1.78 | F55: 243 | G55: 6592 | H55: =$H$3*F55/1000 -> 4221.396 | K55: 51 | L55: 3685 | M55: 89 | N55: 72.3 | O55: 1.86 | P55: 239 | Q55: 6855 | R55: =$R$3*P55/1000 -> 3980.784 | S55: =CEILING(R55/50,0.5) -> 80 | T55: 51 | W55: 81 | X55: 17.998 | Y55: =ROUND(X55/1000,3) -> 0.018 | AA55: 20 | AB55: 0.8 | AC55: 2.39 | AD55: 1.242 | AE55: 0.993 | AF55: 314 | AG55: 40 | AH55: =AE55-AE54 -> 0.016 | AI55: =AB55*1000 -> 800 | AJ55: =ROUND(W55/1000,3) -> 0.081 | AL55: 51 | AM55: =_xlfn.SINGLE(_xlfn.XLOOKUP(AL55,AA:AA,AB:AB))*1000 -> 3310 | AN55: =_xlfn.SINGLE(_xlfn.XLOOKUP(AL55,AA:AA,AE:AE))*1000 -> 6431 | AO55: =+AN55-AN54 -> 195 | AP55: =ROUND(X55/1000,3) -> 0.018
A56: 51 | B56: 3797 | C56: 90 | D56: 74 | E56: 1.8 | F56: 244 | G56: 6835 | H56: =$H$3*F56/1000 -> 4238.768 | K56: 52 | L56: 3773 | M56: 88 | N56: 72.6 | O56: 1.88 | P56: 240 | Q56: 7095 | R56: =$R$3*P56/1000 -> 3997.44 | S56: =CEILING(R56/50,0.5) -> 80 | W56: 82 | X56: 18.097 | Y56: =ROUND(X56/1000,3) -> 0.018 | AA56: 20 | AB56: 0.81 | AC56: 2.39 | AD56: 1.246 | AE56: 1.01 | AF56: 317 | AG56: 41 | AH56: =AE56-AE55 -> 0.017 | AI56: =AB56*1000 -> 810 | AJ56: =ROUND(W56/1000,3) -> 0.082 | AL56: 52 | AM56: =_xlfn.SINGLE(_xlfn.XLOOKUP(AL56,AA:AA,AB:AB))*1000 -> 3380 | AN56: =_xlfn.SINGLE(_xlfn.XLOOKUP(AL56,AA:AA,AE:AE))*1000 -> 6630 | AO56: =+AN56-AN55 -> 199 | AP56: =ROUND(X56/1000,3) -> 0.018
A57: 52 | B57: 3885 | C57: 88 | D57: 75 | E57: 1.82 | F57: 245 | G57: 7080 | H57: =$H$3*F57/1000 -> 4256.14 | K57: 53 | L57: 3859 | M57: 86 | N57: 72.8 | O57: 1.901 | P57: 242 | Q57: 7337 | R57: =$R$3*P57/1000 -> 4030.752 | S57: =CEILING(R57/50,0.5) -> 81 | W57: 83 | X57: 18.196 | Y57: =ROUND(X57/1000,3) -> 0.018 | AA57: 20 | AB57: 0.82 | AC57: 2.39 | AD57: 1.251 | AE57: 1.026 | AF57: 320 | AG57: 41 | AH57: =AE57-AE56 -> 0.016 | AI57: =AB57*1000 -> 820 | AJ57: =ROUND(W57/1000,3) -> 0.083 | AL57: 53 | AM57: =_xlfn.SINGLE(_xlfn.XLOOKUP(AL57,AA:AA,AB:AB))*1000 -> 3440 | AN57: =_xlfn.SINGLE(_xlfn.XLOOKUP(AL57,AA:AA,AE:AE))*1000 -> 6831 | AO57: =+AN57-AN56 -> 201 | AP57: =ROUND(X57/1000,3) -> 0.018
A58: 53 | B58: 3973 | C58: 87 | D58: 75 | E58: 1.84 | F58: 247 | G58: 7326 | H58: =$H$3*F58/1000 -> 4290.884 | K58: 54 | L58: 3944 | M58: 85 | N58: 73 | O58: 1.922 | P58: 243 | Q58: 7580 | R58: =$R$3*P58/1000 -> 4047.408 | S58: =CEILING(R58/50,0.5) -> 81 | W58: 84 | X58: 18.296 | Y58: =ROUND(X58/1000,3) -> 0.018 | AA58: 20 | AB58: 0.83 | AC58: 2.39 | AD58: 1.256 | AE58: 1.043 | AF58: 322 | AG58: 42 | AH58: =AE58-AE57 -> 0.017 | AI58: =AB58*1000 -> 830 | AJ58: =ROUND(W58/1000,3) -> 0.084 | AL58: 54 | AM58: =_xlfn.SINGLE(_xlfn.XLOOKUP(AL58,AA:AA,AB:AB))*1000 -> 3510 | AN58: =_xlfn.SINGLE(_xlfn.XLOOKUP(AL58,AA:AA,AE:AE))*1000 -> 7035 | AO58: =+AN58-AN57 -> 204 | AP58: =ROUND(X58/1000,3) -> 0.018
A59: 54 | B59: 4059 | C59: 86 | D59: 75 | E59: 1.87 | F59: 247 | G59: 7573 | H59: =$H$3*F59/1000 -> 4290.884 | K59: 55 | L59: 4028 | M59: 84 | N59: 73.2 | O59: 1.943 | P59: 245 | Q59: 7825 | R59: =$R$3*P59/1000 -> 4080.72 | S59: =CEILING(R59/50,0.5) -> 82 | W59: 85 | X59: 18.395 | Y59: =ROUND(X59/1000,3) -> 0.018 | AA59: 21 | AB59: 0.84 | AC59: 2.5 | AD59: 1.261 | AE59: 1.063 | AF59: 310 | AG59: 40 | AH59: =AE59-AE58 -> 0.02 | AI59: =AB59*1000 -> 840 | AJ59: =ROUND(W59/1000,3) -> 0.085 | AL59: 55 | AM59: =_xlfn.SINGLE(_xlfn.XLOOKUP(AL59,AA:AA,AB:AB))*1000 -> 3580 | AN59: =_xlfn.SINGLE(_xlfn.XLOOKUP(AL59,AA:AA,AE:AE))*1000 -> 7242 | AO59: =+AN59-AN58 -> 207 | AP59: =ROUND(X59/1000,3) -> 0.018
A60: 55 | B60: 4144 | C60: 85 | D60: 75 | E60: 1.89 | F60: 246 | G60: 7819 | H60: =$H$3*F60/1000 -> 4273.512 | K60: 56 | L60: 4111 | M60: 83 | N60: 73.4 | O60: 1.963 | P60: 245 | Q60: 8070 | R60: =$R$3*P60/1000 -> 4080.72 | S60: =CEILING(R60/50,0.5) -> 82 | W60: 86 | X60: 18.495 | Y60: =ROUND(X60/1000,3) -> 0.018 | AA60: 21 | AB60: 0.85 | AC60: 2.5 | AD60: 1.264 | AE60: 1.075 | AF60: 312 | AG60: 40 | AH60: =AE60-AE59 -> 0.012 | AI60: =AB60*1000 -> 850 | AJ60: =ROUND(W60/1000,3) -> 0.086 | AL60: 56 | AM60: =_xlfn.SINGLE(_xlfn.XLOOKUP(AL60,AA:AA,AB:AB))*1000 -> 3640 | AN60: =_xlfn.SINGLE(_xlfn.XLOOKUP(AL60,AA:AA,AE:AE))*1000 -> 7452 | AO60: =+AN60-AN59 -> 210 | AP60: =ROUND(X60/1000,3) -> 0.018
A61: 56 | B61: 4227 | C61: 83 | D61: 75 | E61: 1.91 | F61: 245 | G61: 8063 | H61: =$H$3*F61/1000 -> 4256.14 | K61: 57 | L61: 4192 | M61: 81 | N61: 73.5 | O61: 1.984 | P61: 245 | Q61: 8315 | R61: =$R$3*P61/1000 -> 4080.72 | S61: =CEILING(R61/50,0.5) -> 82 | W61: 87 | X61: 18.594 | Y61: =ROUND(X61/1000,3) -> 0.019 | AA61: 21 | AB61: 0.86 | AC61: 2.5 | AD61: 1.268 | AE61: 1.09 | AF61: 315 | AG61: 41 | AH61: =AE61-AE60 -> 0.015 | AI61: =AB61*1000 -> 860 | AJ61: =ROUND(W61/1000,3) -> 0.087 | AL61: 0 | AP61: =ROUND(X61/1000,3) -> 0.019
A62: 57 | B62: 4309 | C62: 82 | D62: 76 | E62: 1.93 | F62: 243 | G62: 8306 | H62: =$H$3*F62/1000 -> 4221.396 | K62: 58 | L62: 4272 | M62: 80 | N62: 73.7 | O62: 2.004 | P62: 245 | Q62: 8560 | R62: =$R$3*P62/1000 -> 4080.72 | S62: =CEILING(R62/50,0.5) -> 82 | W62: 88 | X62: 18.694 | Y62: =ROUND(X62/1000,3) -> 0.019 | AA62: 21 | AB62: 0.87 | AC62: 2.5 | AD62: 1.271 | AE62: 1.106 | AF62: 318 | AG62: 41 | AH62: =AE62-AE61 -> 0.016 | AI62: =AB62*1000 -> 870 | AJ62: =ROUND(W62/1000,3) -> 0.088 | AP62: =ROUND(X62/1000,3) -> 0.019
A63: 58 | B63: 4389 | C63: 80 | D63: 76 | E63: 1.95 | F63: 241 | G63: 8547 | H63: =$H$3*F63/1000 -> 4186.652 | K63: 59 | L63: 4350 | M63: 78 | N63: 73.7 | O63: 2.024 | P63: 245 | Q63: 8805 | R63: =$R$3*P63/1000 -> 4080.72 | S63: =CEILING(R63/50,0.5) -> 82 | W63: 89 | X63: 18.793 | Y63: =ROUND(X63/1000,3) -> 0.019 | AA63: 21 | AB63: 0.88 | AC63: 2.5 | AD63: 1.274 | AE63: 1.121 | AF63: 321 | AG63: 42 | AH63: =AE63-AE62 -> 0.015 | AI63: =AB63*1000 -> 880 | AJ63: =ROUND(W63/1000,3) -> 0.089 | AP63: =ROUND(X63/1000,3) -> 0.019
A64: 59 | B64: 4466 | C64: 77 | D64: 76 | E64: 1.97 | F64: 239 | G64: 8786 | H64: =$H$3*F64/1000 -> 4151.908 | K64: 60 | L64: 4427 | M64: 77 | N64: 73.8 | O64: 2.044 | P64: 245 | Q64: 9050 | R64: =$R$3*P64/1000 -> 4080.72 | S64: =CEILING(R64/50,0.5) -> 82 | W64: 90 | X64: 18.892 | Y64: =ROUND(X64/1000,3) -> 0.019 | AA64: 21 | AB64: 0.89 | AC64: 2.5 | AD64: 1.277 | AE64: 1.137 | AF64: 324 | AG64: 42 | AH64: =AE64-AE63 -> 0.016 | AI64: =AB64*1000 -> 890 | AJ64: =ROUND(W64/1000,3) -> 0.09 | AP64: =ROUND(X64/1000,3) -> 0.019
A65: 60 | B65: 4542 | C65: 76 | D65: 76 | E65: 1.99 | F65: 237 | G65: 9022 | H65: =$H$3*F65/1000 -> 4117.164 | K65: 61 | L65: 4502 | M65: 75 | N65: 73.8 | O65: 2.065 | P65: 245 | Q65: 9295 | R65: =$R$3*P65/1000 -> 4080.72 | S65: =CEILING(R65/50,0.5) -> 82 | W65: 91 | X65: 18.992 | Y65: =ROUND(X65/1000,3) -> 0.019 | AA65: 21 | AB65: 0.9 | AC65: 2.5 | AD65: 1.281 | AE65: 1.152 | AF65: 326 | AG65: 43 | AH65: =AE65-AE64 -> 0.015 | AI65: =AB65*1000 -> 900 | AJ65: =ROUND(W65/1000,3) -> 0.091 | AP65: =ROUND(X65/1000,3) -> 0.019
A66: 61 | B66: 4616 | C66: 74 | D66: 76 | E66: 2.01 | F66: 234 | G66: 9256 | H66: =$H$3*F66/1000 -> 4065.048 | K66: 62 | L66: 4576 | M66: 74 | N66: 73.8 | O66: 2.085 | P66: 245 | Q66: 9540 | R66: =$R$3*P66/1000 -> 4080.72 | S66: =CEILING(R66/50,0.5) -> 82 | W66: 92 | X66: 19.091 | Y66: =ROUND(X66/1000,3) -> 0.019 | AA66: 21 | AB66: 0.91 | AC66: 2.5 | AD66: 1.284 | AE66: 1.168 | AF66: 329 | AG66: 43 | AH66: =AE66-AE65 -> 0.016 | AI66: =AB66*1000 -> 910 | AJ66: =ROUND(W66/1000,3) -> 0.092 | AP66: =ROUND(X66/1000,3) -> 0.019
A67: 62 | B67: 4688 | C67: 73 | D67: 76 | E67: 2.02 | F67: 232 | G67: 9488 | H67: =$H$3*F67/1000 -> 4030.304 | K67: 63 | L67: 4649 | M67: 73 | N67: 73.8 | O67: 2.105 | P67: 245 | Q67: 9785 | R67: =$R$3*P67/1000 -> 4080.72 | S67: =CEILING(R67/50,0.5) -> 82 | W67: 93 | X67: 19.191 | Y67: =ROUND(X67/1000,3) -> 0.019 | AA67: 22 | AB67: 0.92 | AC67: 2.61 | AD67: 1.287 | AE67: 1.187 | AF67: 317 | AG67: 42 | AH67: =AE67-AE66 -> 0.019 | AI67: =AB67*1000 -> 920 | AJ67: =ROUND(W67/1000,3) -> 0.093 | AP67: =ROUND(X67/1000,3) -> 0.019
A68: 63 | B68: 4759 | C68: 70 | D68: 76 | E68: 2.04 | F68: 228 | G68: 9716 | H68: =$H$3*F68/1000 -> 3960.816 | S68: =CEILING(R68/50,0.5) -> 0 | W68: 94 | X68: 19.29 | Y68: =ROUND(X68/1000,3) -> 0.019 | AA68: 22 | AB68: 0.93 | AC68: 2.61 | AD68: 1.29 | AE68: 1.2 | AF68: 319 | AG68: 42 | AH68: =AE68-AE67 -> 0.013 | AI68: =AB68*1000 -> 930 | AJ68: =ROUND(W68/1000,3) -> 0.094 | AP68: =ROUND(X68/1000,3) -> 0.019
S69: =CEILING(R69/50,0.5) -> 0 | W69: 95 | X69: 19.466 | Y69: =ROUND(X69/1000,3) -> 0.019 | AA69: 22 | AB69: 0.94 | AC69: 2.61 | AD69: 1.294 | AE69: 1.216 | AF69: 322 | AG69: 43 | AH69: =AE69-AE68 -> 0.016 | AI69: =AB69*1000 -> 940 | AJ69: =ROUND(W69/1000,3) -> 0.095 | AP69: =ROUND(X69/1000,3) -> 0.019
S70: =CEILING(R70/50,0.5) -> 0 | W70: 96 | X70: 19.642 | Y70: =ROUND(X70/1000,3) -> 0.02 | AA70: 22 | AB70: 0.95 | AC70: 2.61 | AD70: 1.297 | AE70: 1.232 | AF70: 3.24 | AG70: 43 | AH70: =AE70-AE69 -> 0.016 | AI70: =AB70*1000 -> 950 | AJ70: =ROUND(W70/1000,3) -> 0.096 | AP70: =ROUND(X70/1000,3) -> 0.02
...

Sheet Simulasi IBOCS
B1: Menu | C1: STD 2015 | D1: STD 2018 | E1: STD SAP 2012/AHP | F1: STD SAP 2015 | G1: STD SAP 2015 SHARE TNP BW | H1: Manual 2015 | I1: Ket | J1: Rumus | K1: IBOCS | L1: No
A2: A | B2: Target BW | C2: =+D2 -> 2200 | D2: =+E2*1000 -> 2200 | E2: 2.2 | F2: =+E2 -> 2.2 | G2: =+F2 -> 2.2 | I2: Target | J2: Input Manual Ambil dari Plan | K2: BW Panen | L2: 21
A3: B | B3: Kebutuhan pakan | C3: =+_xlfn.XLOOKUP(C2,'STD COBB'!L:L,'STD COBB'!Q:Q,"",1) -> 3545 | D3: =+_xlfn.XLOOKUP(D2,'STD COBB'!B:B,'STD COBB'!G:G,"",1) -> 3399 | E3: =+_xlfn.XLOOKUP(E2,'STD SAP'!C:C,'STD SAP'!I:I,"",1) -> 3.644 | F3: =+_xlfn.XLOOKUP(F2,'STD SAP'!X:X,'STD SAP'!AD:AD,"",1) -> 3.37 | G3: =+_xlfn.XLOOKUP(G2,'STD SAP'!X:X,'STD SAP'!AD:AD,"",1) -> 3.37 | J3: ="FI CUM STD dari "&B2 -> FI CUM STD dari Target BW | K3: FI Cum Pakan
A4: C | B4: Populasi + Bonus | C4: =D4 -> 17372 | D4: =E4 -> 17372 | E4: =17200*1.01 -> 17372 | F4: =+E4 -> 17372 | G4: =17200*1.01 -> 17372 | I4: Kondisi sekarang | J4: Initial Stock Plan x 1.01 | K4: Populasi | L4: 3
A5: D | B5: Tanggal CI | C5: =+D5 -> 46099 | D5: =+E5 -> 46099 | E5: 46099 | F5: =+E5 -> 46099 | G5: 46111 | J5: Stardate Plan
A6: E | B6: KG Pakan | C6: =CEILING(C4*C3/1000,50) -> 61600 | D6: =CEILING(D4*D3/1000,50) -> 59050 | E6: =CEILING(E4*E3,50) -> 63350 | F6: =CEILING(F4*F3,50) -> 58550 | G6: =CEILING(G4*G3,50) -> 58550 | J6: =B4&" x "&B3&" , Kelipatan 50" -> Populasi + Bonus x Kebutuhan pakan , Kelipatan 50
A7: F | B7: Tanggal Kunjungan | C7: =+C5+C8 -> 46135 | D7: =+D5+D8 -> 46135 | E7: 46135 | F7: =+F5+F8 -> 46135 | G7: 46147 | J7: Last Date dari GI Pakan | K7: Last Posting Date | L7: 4
A8: G | B8: Usia Kunjungan | C8: =+D8 -> 36 | D8: =+E8 -> 36 | E8: =+E7-E5 -> 36 | F8: =+E8 -> 36 | G8: =+F8 -> 36 | J8: Usia Last date dari GI Pakan | K8: Age | L8: 5
A9: H | B9: BW Kunjungan | C9: =+D9 -> 2016 | D9: =+E9*1000 -> 2016 | E9: 2.016 | F9: =+E9 -> 2.016 | G9: {=AVERAGE(_xlfn._xlws.FILTER('STD SAP'!X:X,'STD SAP'!W:W=_xlfn.XLOOKUP('Simulasi IBOCS'!E9,'STD SAP'!X:X,'STD SAP'!W:W,"",1)-3))} -> 1.7515 | J9: ="Last update input BW, diupayakan sama dengan "&B7 -> Last update input BW, diupayakan sama dengan Tanggal Kunjungan | K9: BW | L9: 8
A10: J | B10: Mort Kunjungan | C10: =+D10 -> 716 | D10: =+E10 -> 716 | E10: 716 | F10: =+E10 -> 716 | G10: 716 | J10: ="Total Kematian hingga "&B7 -> Total Kematian hingga Tanggal Kunjungan | K10: Mort | L10: 6
A11: K | B11: Last Stok kunjungan | C11: =+C4-C10 -> 16656 | D11: =+C11 -> 16656 | E11: =+D11 -> 16656 | F11: =+E11 -> 16656 | G11: =+F11 -> 16656 | J11: =B4&" - "&B10&" - Total Panen Sebelum "&B7 -> Populasi + Bonus - Mort Kunjungan - Total Panen Sebelum Tanggal Kunjungan | K11: Last Populasi | L11: 7
A12: L | B12: FCR | E12: =ROUND(+E14/E11/E9,3) -> 1.549 | F12: =ROUND(+F14/F11/F9,3) -> 1.549 | G12: =ROUND(+G14/G11/G9,3) -> 1.782 | J12: =B14&" / ("&B11&" x "&B9&")" -> Pakan Terpakai / (Last Stok kunjungan x BW Kunjungan) | K12: FCR | L12: 9
A13: M | B13: Pakan Terkirim | C13: =+D13 -> 57000 | D13: =+E13 -> 57000 | E13: 57000 | F13: =+E13 -> 57000 | G13: 57000 | J13: Total Pakan dr GRPO+IT+PO+ITR yang sudah dibuat | K13: GRPO/IT/PO/ITR | L13: 12-13
A14: N | B14: Pakan Terpakai | C14: =+D14 -> 52000 | D14: =+E14 -> 52000 | E14: =52000 -> 52000 | F14: =+E14 -> 52000 | G14: =52000 -> 52000 | J14: ="Total GI Pakan hingga "&B7 -> Total GI Pakan hingga Tanggal Kunjungan
A15: O | B15: Pakan Tersisa | C15: =+C13-C14 -> 5000 | D15: =+D13-D14 -> 5000 | E15: =+E13-E14 -> 5000 | F15: =+F13-F14 -> 5000 | G15: =+G13-G14 -> 5000 | I15: Perkiraan sekarang | J15: ="Sisa Total Pakan "&B13&" - "&B14 -> Sisa Total Pakan Pakan Terkirim - Pakan Terpakai | K15: Last Stock | L15: 14
A16: P | B16: Usia Sekarang | E16: =TODAY()-E5 -> 196 | F16: =TODAY()-F5 -> 196 | G16: =TODAY()-G5 -> 184 | J16: ="Today() - "&B5 -> Today() - Tanggal CI | K16: Age Now | L16: 15
A17: Q | B17: Panen Tambahan | E17: 8219 | F17: =+E17 -> 8219 | G17: 8219 | J17: Input Manual perkiraan Harvest yang telah diinfokan | K17: Ekor | L17: 17
A18: R | B18: Stock Akhir | E18: =+E11-E17 -> 8437 | F18: =+F11-F17 -> 8437 | G18: =+G11-G17 -> 8437 | J18: ="Sisa Ayam dari "&B11&" - "&B17 -> Sisa Ayam dari Last Stok kunjungan - Panen Tambahan
A19: S | B19: Tanggal Akhir | E19: 46136 | F19: =IF(E17="","",E19) -> 46136 | G19: 46148 | J19: Input Manual Info Tanggal Terakhir Panen | K19: Tanggal | L19: 16
A20: T | B20: Usia Akhir | E20: =IF(E19<>"",E19-E5,E8) -> 37 | F20: =IF(F19<>"",F19-F5,F8) -> 37 | G20: =IF(G19<>"",G19-G5,G8) -> 37 | J20: =B19&" - "&B7 -> Tanggal Akhir - Tanggal Kunjungan
A21: U | B21: CUM FI ACT | C21: =ROUND(+C14/C4*1000,0) -> 2993 | D21: =ROUND(+D14/D4*1000,0) -> 2993 | E21: =ROUND(+E14/E4,3) -> 2.993 | F21: =ROUND(+F14/F4,3) -> 2.993 | G21: =ROUND(+G14/G4,3) -> 2.993 | J21: =B14&" : "&B4 -> Pakan Terpakai : Populasi + Bonus | K21: FI Act | L21: 10
A22: V | B22: CUM FI Sampai panen | G22: {=IF( OR(G19="",G19<=G7), G21, MIN( _xlfn._xlws.FILTER( 'STD SAP'!AD:AD, 'STD SAP'!W:W= _xlfn.XLOOKUP(G21,'STD SAP'!AD:AD,'STD SAP'!W:W,"",1)+G20-G8 ) ) )} -> 3.163 | J22: ="Jika "&B19&" =kosong atau "&B19&" <= "&B7&", maka "&B21&" , FI min dari Usia (Usia STD dari "&B21&" ) + "&B20&" - "&B8 -> Jika Tanggal Akhir =kosong atau Tanggal Akhir <= Tanggal Kunjungan, maka CUM FI ACT , FI min dari Usia (Usia STD dari CUM FI ACT ) + Usia Akhir - Usia Kunjungan
A23: W | B23: Pakan Pakai Sampai Panen | G23: =MIN(CEILING(G18*(G22-G21),50), G15) -> 1450 | J23: =B18&" x ("&B22&" - "&B21&"), Pembulatan kelipatan 50 maks "&B15 -> Stock Akhir x (CUM FI Sampai panen - CUM FI ACT), Pembulatan kelipatan 50 maks Pakan Tersisa
A24: X | B24: CUM FI Terima Pakan | C24: =+_xlfn.XLOOKUP(C9,'STD COBB'!L:L,'STD COBB'!Q:Q,"",-1) -> 2981 | D24: =+_xlfn.XLOOKUP(D9,'STD COBB'!B:B,'STD COBB'!G:G,"",-1) -> 2870 | E24: =+_xlfn.XLOOKUP(E9,'STD SAP'!C:C,'STD SAP'!I:I,"",-1) -> 3.414 | F24: =+_xlfn.XLOOKUP(F9,'STD SAP'!X:X,'STD SAP'!AD:AD,"",-1) -> 3.023 | G24: =ROUND(+G13/G4,3) -> 3.281 | J24: FI CUM Kiriman Pakan | K24: FI CUM Terima Pakan | L24: 11
A25: Y | B25: CUM FI Sisa Pakan | C25: =ROUND(+C15/C11*1000,0) -> 300 | D25: =ROUND(+D15/D11*1000,0) -> 300 | E25: =IF(E17<>"",ROUND(+E15/E18,3),ROUND(+E15/E11,3)) -> 0.593 | F25: =IF(F17<>"",ROUND(+F15/F18,3),ROUND(+F15/F11,3)) -> 0.593 | G25: =ROUND((G15-G23)/G18,3) -> 0.421 | J25: ="("&B15&" - "&B23&") : "&B18 -> (Pakan Tersisa - Pakan Pakai Sampai Panen) : Stock Akhir
A26: Z | B26: CUM FI STD Total | C26: =+C21+C25 -> 3293 | D26: =+D21+D25 -> 3293 | E26: =+E21+E25 -> 3.586 | F26: =+F21+F25 -> 3.586 | G26: =+G22+G25 -> 3.584 | J26: =B22&" + "&B25 -> CUM FI Sampai panen + CUM FI Sisa Pakan
A27: AA | B27: Usia CUM FI STD 1 | C27: =_xlfn.XLOOKUP(C26,'STD COBB'!Q:Q,'STD COBB'!K:K,"",-1) -> 34 | D27: =_xlfn.XLOOKUP(D26,'STD COBB'!G:G,'STD COBB'!A:A,"",-1) -> 34 | E27: =_xlfn.XLOOKUP(E26,'STD SAP'!I:I,'STD SAP'!B:B,"",-1) -> 35 | F27: =_xlfn.XLOOKUP(F26,'STD SAP'!AD:AD,'STD SAP'!W:W,"",-1) -> 36 | G27: =_xlfn.XLOOKUP(G26,'STD SAP'!AD:AD,'STD SAP'!W:W,"",1) -> 36 | J27: ="Usia STD dari "&B26 -> Usia STD dari CUM FI STD Total
A28: AB | B28: Usia CUM FI STD 2 | C28: =_xlfn.XLOOKUP(C9,'STD COBB'!L:L,'STD COBB'!K:K,"",-1) -> 33 | D28: =_xlfn.XLOOKUP(D9,'STD COBB'!B:B,'STD COBB'!A:A,"",-1) -> 32 | E28: =_xlfn.XLOOKUP(E9,'STD SAP'!C:C,'STD SAP'!B:B,"",-1) -> 34 | F28: =_xlfn.XLOOKUP(F9,'STD SAP'!X:X,'STD SAP'!W:W,"",-1) -> 33 | G28: =_xlfn.XLOOKUP(G22,'STD SAP'!AD:AD,'STD SAP'!W:W,"",1) -> 34 | J28: ="Usia STD dari "&B22 -> Usia STD dari CUM FI Sampai panen
A29: AC | B29: Usia Habis Pakan | C29: =+C27-C28+C8 -> 37 | D29: =+D27-D28+D8 -> 38 | E29: =+E27-E28+E8 -> 37 | F29: =+F27-F28+F8 -> 39 | G29: =IF(G26<=G22,G20,+G27-G28+G20) -> 39 | J29: ="Jika "&B26&" <= "&B22&", maka "&B20&", "&B27&" - "&B28&" + "&B20 -> Jika CUM FI STD Total <= CUM FI Sampai panen, maka Usia Akhir, Usia CUM FI STD 1 - Usia CUM FI STD 2 + Usia Akhir | K29: Age Pakan Habis | L29: 19
A30: AD | B30: Tanggal Habis Pakan | C30: =+C5+C29 -> 46136 | D30: =+D5+D29 -> 46137 | E30: =+E5+E29 -> 46136 | F30: =+F5+F29 -> 46138 | G30: =+G5+G29 -> 46150 | J30: =B5&" + "&B29 -> Tanggal CI + Usia Habis Pakan | K30: Date Pakan Habis | L30: 18
A31: AE | B31: Diff Hari | C31: =+C29-C8 -> 1 | D31: =+D29-D8 -> 2 | E31: =+E29-E8 -> 1 | F31: =+F29-F8 -> 3 | G31: =+G30-TODAY() -> -145 | J31: =B29&" - "&B8 -> Usia Habis Pakan - Usia Kunjungan | K31: Diff Pakan Habis | L31: 20
A32: AF | B32: Kekurangan Pakan | C32: =+C6-C13 -> 4600 | D32: =+D6-D13 -> 2050 | E32: =+E6-E13 -> 6350 | F32: =+F6-F13 -> 1550 | G32: =+G6-G13 -> 1550 | I32: Perkiraan Kedepan | J32: =B6&" - "&B13 -> KG Pakan - Pakan Terkirim | K32: Sisa Kebutuhan | L32: 23
A33: AG | B33: Tanggal Order | C33: =+D33 -> 46137 | D33: =+E33 -> 46137 | E33: 46137 | F33: =E33 -> 46137 | G33: 46149 | J33: Input Manual | K33: Tanggal Order Pakan | L33: 24
A34: AH | B34: Order Pakan | C34: =+D34 -> 2500 | D34: =+E34 -> 2500 | E34: 2500 | F34: =+E34 -> 2500 | G34: 2500 | J34: Jumlah Total dari masing2 jenis Pakan yang diinput manual | K34: Total Jumlah Order | L34: 33
A35: AI | B35: Total Pakan Tersisa | C35: =+C34+C15 -> 7500 | D35: =+D34+D15 -> 7500 | E35: =+E34+E15 -> 7500 | F35: =+F34+F15 -> 7500 | G35: =+G34+G15-G23 -> 6050 | J35: =B15&" + "&B34&" - "&B23 -> Pakan Tersisa + Order Pakan - Pakan Pakai Sampai Panen
A36: AJ | B36: CUM FI Sisa Pakan | C36: =+C35/C11*1000 -> 450.28818 | D36: =+D35/D11*1000 -> 450.28818 | E36: =ROUND(+E35/E11,3) -> 0.45 | F36: =IF(F17<>"",ROUND(+F35/F18,3),ROUND(+F35/F11,3)) -> 0.889 | G36: =ROUND(+G35/G18,3) -> 0.717 | J36: =B35&" : "&B18 -> Total Pakan Tersisa : Stock Akhir
A37: AK | B37: CUM FI STD Total | C37: =+C21+C36 -> 3443.2882 | D37: =+D21+D36 -> 3443.2882 | E37: =+E21+E36 -> 3.443 | F37: =+F21+F36 -> 3.882 | G37: =+G22+G36 -> 3.88 | J37: =B22&" + "&B36 -> CUM FI Sampai panen + CUM FI Sisa Pakan
A38: AL | B38: Usia CUM FI STD 3 | C38: =_xlfn.XLOOKUP(C37,'STD COBB'!Q:Q,'STD COBB'!K:K,"",-1) -> 35 | D38: =_xlfn.XLOOKUP(D37,'STD COBB'!G:G,'STD COBB'!A:A,"",-1) -> 35 | E38: =_xlfn.XLOOKUP(E37,'STD SAP'!I:I,'STD SAP'!B:B,"",-1) -> 35 | F38: =_xlfn.XLOOKUP(F37,'STD SAP'!AD:AD,'STD SAP'!W:W,"",-1) -> 37 | G38: =_xlfn.XLOOKUP(G37,'STD SAP'!AD:AD,'STD SAP'!W:W,"",-1) -> 37 | J38: ="Usia STD dari "&B37 -> Usia STD dari CUM FI STD Total
A39: AM | B39: Usia Habis Pakan | C39: =+C38-C28+C8 -> 38 | D39: =+D38-D28+D8 -> 39 | E39: =+E38-E28+E8 -> 37 | F39: =+F38-F28+F8 -> 40 | G39: =IF(G37<=G26,G29,+G38-G28+G29) -> 42 | J39: ="Jika "&B37&" <= "&B26&", maka "&B29&", "&B38&" - "&B28&" + "&B29 -> Jika CUM FI STD Total <= CUM FI STD Total, maka Usia Habis Pakan, Usia CUM FI STD 3 - Usia CUM FI STD 2 + Usia Habis Pakan | K39: Age Estimasi Pakan Habis | L39: 35
A40: AN | B40: Tanggal Habis Pakan | C40: =+C5+C39 -> 46137 | D40: =+D5+D39 -> 46138 | E40: =+E5+E39 -> 46136 | F40: =+F5+F39 -> 46139 | G40: =+G5+G39 -> 46153 | J40: =B5&" + "&B39 -> Tanggal CI + Usia Habis Pakan | K40: Date Estimasi Pakan Habis | L40: 34
...

Sheet Layout IBOCS
A1: No | B1: No Plan | C1: Plan Desc | D1: Populasi | G1: Status Last Posting | T1: Age Now | U1: Panen Parsial | AA1: Pakan Habis | AJ1: BW PANEN | AK1: Kebutuhan Minggu Depan | AL1: Sisa Kebutuhan | AM1: ORDER | AW1: Estimate Habis Kapan | BD1: LOKASI
E2: Tanggal CI | F2: Kebutuhan Pakan | G2: Last Posting Date | H2: Age | I2: Mort ekor | J2: Last Populasi | K2: BW | L2: FCR | M2: Diff FCR | N2: FI Act | O2: FI Cum Pakan Terima | P2: GRPO/IT | Q2: PO/ITR | R2: GI | S2: Last Stok | U2: Date | V2: Ekor | W2: Date SAP | X2: Ekor SAP | Y2: Stok setelah Panen | Z2: Usia smp Panen | AA2: Date | AB2: Age | AC2: Diff | AD2: FI CUM Panen | AE2: Pakan Sampai Panen | AF2: FI CUM Sisa Pakan | AG2: FI CUM TOTAL | AH2: USIA FI CUM PANEN | AI2: USIA FI CUM TOTAL | AM2: Tanggal | AN2: Jenis Pakan 1 | AO2: Jumlah | AP2: Jenis Pakan 2 | AQ2: Jumlah | AR2: Jenis Pakan 3 | AS2: Jumlah | AT2: Jenis Pakan 4 | AU2: Jumlah | AV2: TOTAL | AW2: Date | AX2: Age | AY2: Diff | AZ2: Total Pakan Sisa | BA2: FI Cum Sisa Pakan | BB2: FI CUM Total | BC2: Usia FI CUM Total | BF2: SIDOARJO
A3: 1 | B3: 1000001 | C3: JG01-Silvy 1 S.1 (Update KHK, Panen Setelah Share, Seting Pakan) | D3: =17200*1.01 -> 17372 | E3: 46111 | F3: =CEILING(_xlfn.XLOOKUP(AJ3,'STD SAP'!X:X,'STD SAP'!AD:AD)*D3,50) -> 58550 | G3: 46147 | H3: =IF(G3<>"",G3-E3,0) -> 36 | I3: 716 | J3: =IF(E3<>"",D3-I3,"") -> 16656 | K3: 2.016 | L3: =IF(K3<>"",R3/K3/J3,"") -> 1.5486102 | M3: =IF(L3<>"",L3-_xlfn.XLOOKUP(K3,'STD SAP'!X:X,'STD SAP'!AA:AA),"") -> 0.048610158 | N3: =IF(R3<>"",ROUND(R3/D3,3),0) -> 2.993 | O3: =IF(S3<>"",ROUND((P3+Q3)/D3,3),0) -> 3.281 | P3: 55000 | Q3: 2000 | R3: 52000 | S3: =IF(SUM(P3:Q3)<>0,+P3+Q3-R3,0) -> 5000 | T3: =IF(E3<>"",IF(E3<TODAY(),TODAY()-E3,0),"") -> 184 | U3: 46148 | V3: 8219 | Y3: =IF(D3<>"",J3-V3-X3,"") -> 8437 | Z3: =IF( OR(MAX(U3,W3)<G3, COUNTA(U3,W3)=0), H3, MAX(U3,W3)-E3 ) -> 37 | AA3: =IF(E3<>"",E3+AB3,"") -> 46150 | AB3: =IF(AG3<=AD3,Z3,AI3-AH3+Z3) -> 39 | AC3: =IF(E3<>"",AA3-TODAY(),"") -> -145 | AD3: =IF(OR(U3="",U3<=G3),N3,_xlfn.XLOOKUP(Z3-H3+_xlfn.XLOOKUP(N3,'STD SAP'!AD:AD,'STD SAP'!W:W,"",1),'STD SAP'!W:W,'STD SAP'!AD:AD)) -> 3.163 | AE3: =IF(Y3<>"",MIN(CEILING(Y3*(AD3-N3),50),S3),0) -> 1450 | AF3: =IF(S3<>"",ROUND((S3-AE3)/Y3,3),"") -> 0.421 | AG3: =IF(AF3<>"",+AD3+AF3,0) -> 3.584 | AH3: =IF(AD3<>"",_xlfn.XLOOKUP(AD3,'STD SAP'!AD:AD,'STD SAP'!W:W,"",1),"") -> 34 | AI3: =IF(AG3<>"",_xlfn.XLOOKUP(AG3,'STD SAP'!AD:AD,'STD SAP'!W:W,"",1),"") -> 36 | AJ3: 2.2 | AL3: =F3-P3-Q3 -> 1550 | AM3: 46149 | AN3: GF 511 SUPER | AO3: 2000 | AV3: =IF(AO3<>"",AO3+AQ3+AS3+AU3,0) -> 2000 | AW3: =E3+AX3 -> 46153 | AX3: =IF(BB3<=AG3,AB3,BC3+AB3-AH3) -> 42 | AY3: =AW3-TODAY() -> -142 | AZ3: =S3+AV3-AE3 -> 5550 | BA3: =ROUND(AZ3/Y3,3) -> 0.658 | BB3: =BA3+AD3 -> 3.821 | BC3: =_xlfn.XLOOKUP(BB3,'STD SAP'!AD:AD,'STD SAP'!W:W,"",1) -> 37 | BD3: SIDOARJO | BF3: SEMARANG
A4: 2 | B4: 1000002 | C4: JG02-Jeane 1 S.1 (Update KHK, Panen Setelah Share, Tanpa Seting Pakan) | D4: =17200*1.01 -> 17372 | E4: 46111 | F4: =CEILING(_xlfn.XLOOKUP(AJ4,'STD SAP'!X:X,'STD SAP'!AD:AD)*D4,50) -> 58550 | G4: 46147 | H4: =IF(G4<>"",G4-E4,0) -> 36 | I4: 716 | J4: =IF(E4<>"",D4-I4,"") -> 16656 | K4: 2.016 | L4: =IF(K4<>"",R4/K4/J4,"") -> 1.5486102 | M4: =IF(L4<>"",L4-_xlfn.XLOOKUP(K4,'STD SAP'!X:X,'STD SAP'!AA:AA),"") -> 0.048610158 | N4: =IF(R4<>"",ROUND(R4/D4,3),0) -> 2.993 | O4: =IF(S4<>"",ROUND((P4+Q4)/D4,3),0) -> 3.281 | P4: 55000 | Q4: 2000 | R4: 52000 | S4: =IF(SUM(P4:Q4)<>0,+P4+Q4-R4,0) -> 5000 | T4: =IF(E4<>"",IF(E4<TODAY(),TODAY()-E4,0),"") -> 184 | U4: 46148 | V4: 8219 | Y4: =IF(D4<>"",J4-V4-X4,"") -> 8437 | Z4: =IF( OR(MAX(U4,W4)<G4, COUNTA(U4,W4)=0), H4, MAX(U4,W4)-E4 ) -> 37 | AA4: =IF(E4<>"",E4+AB4,"") -> 46150 | AB4: =IF(AG4<=AD4,Z4,AI4-AH4+Z4) -> 39 | AC4: =IF(E4<>"",AA4-TODAY(),"") -> -145 | AD4: =IF(OR(U4="",U4<=G4),N4,_xlfn.XLOOKUP(Z4-H4+_xlfn.XLOOKUP(N4,'STD SAP'!AD:AD,'STD SAP'!W:W,"",1),'STD SAP'!W:W,'STD SAP'!AD:AD)) -> 3.163 | AE4: =IF(Y4<>"",MIN(CEILING(Y4*(AD4-N4),50),S4),0) -> 1450 | AF4: =IF(S4<>"",ROUND((S4-AE4)/Y4,3),"") -> 0.421 | AG4: =IF(AF4<>"",+AD4+AF4,0) -> 3.584 | AH4: =IF(AD4<>"",_xlfn.XLOOKUP(AD4,'STD SAP'!AD:AD,'STD SAP'!W:W,"",1),"") -> 34 | AI4: =IF(AG4<>"",_xlfn.XLOOKUP(AG4,'STD SAP'!AD:AD,'STD SAP'!W:W,"",1),"") -> 36 | AJ4: 2.2 | AL4: =F4-P4-Q4 -> 1550 | AV4: =IF(AO4<>"",AO4+AQ4+AS4+AU4,0) -> 0 | AW4: =E4+AX4 -> 46150 | AX4: =IF(BB4<=AG4,AB4,BC4+AB4-AH4) -> 39 | AY4: =AW4-TODAY() -> -145 | AZ4: =S4+AV4-AE4 -> 3550 | BA4: =ROUND(AZ4/Y4,3) -> 0.421 | BB4: =BA4+AD4 -> 3.584 | BC4: =_xlfn.XLOOKUP(BB4,'STD SAP'!AD:AD,'STD SAP'!W:W,"",1) -> 36 | BD4: SIDOARJO | BF4: SRAGEN
A5: 3 | B5: 1000003 | C5: JG03-Anto 1 S.1 (Update KHK, Panen Sebelum/Pas Share , Seting Pakan) | D5: =17200*1.01 -> 17372 | E5: 46111 | F5: =CEILING(_xlfn.XLOOKUP(AJ5,'STD SAP'!X:X,'STD SAP'!AD:AD)*D5,50) -> 58550 | G5: 46147 | H5: =IF(G5<>"",G5-E5,0) -> 36 | I5: 716 | J5: =IF(E5<>"",D5-I5,"") -> 16656 | K5: 2.016 | L5: =IF(K5<>"",R5/K5/J5,"") -> 1.5486102 | M5: =IF(L5<>"",L5-_xlfn.XLOOKUP(K5,'STD SAP'!X:X,'STD SAP'!AA:AA),"") -> 0.048610158 | N5: =IF(R5<>"",ROUND(R5/D5,3),0) -> 2.993 | O5: =IF(S5<>"",ROUND((P5+Q5)/D5,3),0) -> 3.281 | P5: 55000 | Q5: 2000 | R5: 52000 | S5: =IF(SUM(P5:Q5)<>0,+P5+Q5-R5,0) -> 5000 | T5: =IF(E5<>"",IF(E5<TODAY(),TODAY()-E5,0),"") -> 184 | W5: 46145 | X5: 8219 | Y5: =IF(D5<>"",J5-V5-X5,"") -> 8437 | Z5: =IF( OR(MAX(U5,W5)<G5, COUNTA(U5,W5)=0), H5, MAX(U5,W5)-E5 ) -> 36 | AA5: =IF(E5<>"",E5+AB5,"") -> 46150 | AB5: =IF(AG5<=AD5,Z5,AI5-AH5+Z5) -> 39 | AC5: =IF(E5<>"",AA5-TODAY(),"") -> -145 | AD5: =IF(OR(U5="",U5<=G5),N5,_xlfn.XLOOKUP(Z5-H5+_xlfn.XLOOKUP(N5,'STD SAP'!AD:AD,'STD SAP'!W:W,"",1),'STD SAP'!W:W,'STD SAP'!AD:AD)) -> 2.993 | AE5: =IF(Y5<>"",MIN(CEILING(Y5*(AD5-N5),50),S5),0) -> 0 | AF5: =IF(S5<>"",ROUND((S5-AE5)/Y5,3),"") -> 0.593 | AG5: =IF(AF5<>"",+AD5+AF5,0) -> 3.586 | AH5: =IF(AD5<>"",_xlfn.XLOOKUP(AD5,'STD SAP'!AD:AD,'STD SAP'!W:W,"",1),"") -> 33 | AI5: =IF(AG5<>"",_xlfn.XLOOKUP(AG5,'STD SAP'!AD:AD,'STD SAP'!W:W,"",1),"") -> 36 | AJ5: 2.2 | AL5: =F5-P5-Q5 -> 1550 | AM5: 46149 | AN5: GF 511 SUPER | AO5: 2000 | AV5: =IF(AO5<>"",AO5+AQ5+AS5+AU5,0) -> 2000 | AW5: =E5+AX5 -> 46154 | AX5: =IF(BB5<=AG5,AB5,BC5+AB5-AH5) -> 43 | AY5: =AW5-TODAY() -> -141 | AZ5: =S5+AV5-AE5 -> 7000 | BA5: =ROUND(AZ5/Y5,3) -> 0.83 | BB5: =BA5+AD5 -> 3.823 | BC5: =_xlfn.XLOOKUP(BB5,'STD SAP'!AD:AD,'STD SAP'!W:W,"",1) -> 37 | BD5: SIDOARJO | BF5: CIREBON
A6: 4 | B6: 1000004 | C6: JG01-Silvy 1 S.2 (Update KHK, Panen Sebelum/Pas Share, Tanpa Seting Pakan) | D6: =17200*1.01 -> 17372 | E6: 46111 | F6: =CEILING(_xlfn.XLOOKUP(AJ6,'STD SAP'!X:X,'STD SAP'!AD:AD)*D6,50) -> 58550 | G6: 46147 | H6: =IF(G6<>"",G6-E6,0) -> 36 | I6: 716 | J6: =IF(E6<>"",D6-I6,"") -> 16656 | K6: 2.016 | L6: =IF(K6<>"",R6/K6/J6,"") -> 1.5486102 | M6: =IF(L6<>"",L6-_xlfn.XLOOKUP(K6,'STD SAP'!X:X,'STD SAP'!AA:AA),"") -> 0.048610158 | N6: =IF(R6<>"",ROUND(R6/D6,3),0) -> 2.993 | O6: =IF(S6<>"",ROUND((P6+Q6)/D6,3),0) -> 3.281 | P6: 55000 | Q6: 2000 | R6: 52000 | S6: =IF(SUM(P6:Q6)<>0,+P6+Q6-R6,0) -> 5000 | T6: =IF(E6<>"",IF(E6<TODAY(),TODAY()-E6,0),"") -> 184 | W6: 46145 | X6: 8219 | Y6: =IF(D6<>"",J6-V6-X6,"") -> 8437 | Z6: =IF( OR(MAX(U6,W6)<G6, COUNTA(U6,W6)=0), H6, MAX(U6,W6)-E6 ) -> 36 | AA6: =IF(E6<>"",E6+AB6,"") -> 46150 | AB6: =IF(AG6<=AD6,Z6,AI6-AH6+Z6) -> 39 | AC6: =IF(E6<>"",AA6-TODAY(),"") -> -145 | AD6: =IF(OR(U6="",U6<=G6),N6,_xlfn.XLOOKUP(Z6-H6+_xlfn.XLOOKUP(N6,'STD SAP'!AD:AD,'STD SAP'!W:W,"",1),'STD SAP'!W:W,'STD SAP'!AD:AD)) -> 2.993 | AE6: =IF(Y6<>"",MIN(CEILING(Y6*(AD6-N6),50),S6),0) -> 0 | AF6: =IF(S6<>"",ROUND((S6-AE6)/Y6,3),"") -> 0.593 | AG6: =IF(AF6<>"",+AD6+AF6,0) -> 3.586 | AH6: =IF(AD6<>"",_xlfn.XLOOKUP(AD6,'STD SAP'!AD:AD,'STD SAP'!W:W,"",1),"") -> 33 | AI6: =IF(AG6<>"",_xlfn.XLOOKUP(AG6,'STD SAP'!AD:AD,'STD SAP'!W:W,"",1),"") -> 36 | AJ6: 2.2 | AL6: =F6-P6-Q6 -> 1550 | AV6: =IF(AO6<>"",AO6+AQ6+AS6+AU6,0) -> 0 | AW6: =E6+AX6 -> 46150 | AX6: =IF(BB6<=AG6,AB6,BC6+AB6-AH6) -> 39 | AY6: =AW6-TODAY() -> -145 | AZ6: =S6+AV6-AE6 -> 5000 | BA6: =ROUND(AZ6/Y6,3) -> 0.593 | BB6: =BA6+AD6 -> 3.586 | BC6: =_xlfn.XLOOKUP(BB6,'STD SAP'!AD:AD,'STD SAP'!W:W,"",1) -> 36 | BD6: SIDOARJO | BF6: TULUNGAGUNG
A7: 5 | B7: 1000005 | C7: JG02-Jeane 1 S.2 (Update KHK, Tanpa Panen, Seting Pakan) | D7: =17200*1.01 -> 17372 | E7: 46111 | F7: =CEILING(_xlfn.XLOOKUP(AJ7,'STD SAP'!X:X,'STD SAP'!AD:AD)*D7,50) -> 58550 | G7: 46147 | H7: =IF(G7<>"",G7-E7,0) -> 36 | I7: 716 | J7: =IF(E7<>"",D7-I7,"") -> 16656 | K7: 2.016 | L7: =IF(K7<>"",R7/K7/J7,"") -> 1.5486102 | M7: =IF(L7<>"",L7-_xlfn.XLOOKUP(K7,'STD SAP'!X:X,'STD SAP'!AA:AA),"") -> 0.048610158 | N7: =IF(R7<>"",ROUND(R7/D7,3),0) -> 2.993 | O7: =IF(S7<>"",ROUND((P7+Q7)/D7,3),0) -> 3.281 | P7: 55000 | Q7: 2000 | R7: 52000 | S7: =IF(SUM(P7:Q7)<>0,+P7+Q7-R7,0) -> 5000 | T7: =IF(E7<>"",IF(E7<TODAY(),TODAY()-E7,0),"") -> 184 | Y7: =IF(D7<>"",J7-V7-X7,"") -> 16656 | Z7: =IF( OR(MAX(U7,W7)<G7, COUNTA(U7,W7)=0), H7, MAX(U7,W7)-E7 ) -> 36 | AA7: =IF(E7<>"",E7+AB7,"") -> 46148 | AB7: =IF(AG7<=AD7,Z7,AI7-AH7+Z7) -> 37 | AC7: =IF(E7<>"",AA7-TODAY(),"") -> -147 | AD7: =IF(OR(U7="",U7<=G7),N7,_xlfn.XLOOKUP(Z7-H7+_xlfn.XLOOKUP(N7,'STD SAP'!AD:AD,'STD SAP'!W:W,"",1),'STD SAP'!W:W,'STD SAP'!AD:AD)) -> 2.993 | AE7: =IF(Y7<>"",MIN(CEILING(Y7*(AD7-N7),50),S7),0) -> 0 | AF7: =IF(S7<>"",ROUND((S7-AE7)/Y7,3),"") -> 0.3 | AG7: =IF(AF7<>"",+AD7+AF7,0) -> 3.293 | AH7: =IF(AD7<>"",_xlfn.XLOOKUP(AD7,'STD SAP'!AD:AD,'STD SAP'!W:W,"",1),"") -> 33 | AI7: =IF(AG7<>"",_xlfn.XLOOKUP(AG7,'STD SAP'!AD:AD,'STD SAP'!W:W,"",1),"") -> 34 | AJ7: 2.2 | AL7: =F7-P7-Q7 -> 1550 | AM7: 46149 | AN7: GF 511 SUPER | AO7: 5000 | AV7: =IF(AO7<>"",AO7+AQ7+AS7+AU7,0) -> 5000 | AW7: =E7+AX7 -> 46151 | AX7: =IF(BB7<=AG7,AB7,BC7+AB7-AH7) -> 40 | AY7: =AW7-TODAY() -> -144 | AZ7: =S7+AV7-AE7 -> 10000 | BA7: =ROUND(AZ7/Y7,3) -> 0.6 | BB7: =BA7+AD7 -> 3.593 | BC7: =_xlfn.XLOOKUP(BB7,'STD SAP'!AD:AD,'STD SAP'!W:W,"",1) -> 36 | BD7: SIDOARJO | BF7: MAGELANG
A8: 6 | B8: 1000006 | C8: JG03-Anto 1 S.2 (Update KHK, Tanpa Panen, Tanpa Seting Pakan) | D8: =17200*1.01 -> 17372 | E8: 46111 | F8: =CEILING(_xlfn.XLOOKUP(AJ8,'STD SAP'!X:X,'STD SAP'!AD:AD)*D8,50) -> 58550 | G8: 46147 | H8: =IF(G8<>"",G8-E8,0) -> 36 | I8: 716 | J8: =IF(E8<>"",D8-I8,"") -> 16656 | K8: 2.016 | L8: =IF(K8<>"",R8/K8/J8,"") -> 1.5486102 | M8: =IF(L8<>"",L8-_xlfn.XLOOKUP(K8,'STD SAP'!X:X,'STD SAP'!AA:AA),"") -> 0.048610158 | N8: =IF(R8<>"",ROUND(R8/D8,3),0) -> 2.993 | O8: =IF(S8<>"",ROUND((P8+Q8)/D8,3),0) -> 3.281 | P8: 55000 | Q8: 2000 | R8: 52000 | S8: =IF(SUM(P8:Q8)<>0,+P8+Q8-R8,0) -> 5000 | T8: =IF(E8<>"",IF(E8<TODAY(),TODAY()-E8,0),"") -> 184 | Y8: =IF(D8<>"",J8-V8-X8,"") -> 16656 | Z8: =IF( OR(MAX(U8,W8)<G8, COUNTA(U8,W8)=0), H8, MAX(U8,W8)-E8 ) -> 36 | AA8: =IF(E8<>"",E8+AB8,"") -> 46148 | AB8: =IF(AG8<=AD8,Z8,AI8-AH8+Z8) -> 37 | AC8: =IF(E8<>"",AA8-TODAY(),"") -> -147 | AD8: =IF(OR(U8="",U8<=G8),N8,_xlfn.XLOOKUP(Z8-H8+_xlfn.XLOOKUP(N8,'STD SAP'!AD:AD,'STD SAP'!W:W,"",1),'STD SAP'!W:W,'STD SAP'!AD:AD)) -> 2.993 | AE8: =IF(Y8<>"",MIN(CEILING(Y8*(AD8-N8),50),S8),0) -> 0 | AF8: =IF(S8<>"",ROUND((S8-AE8)/Y8,3),"") -> 0.3 | AG8: =IF(AF8<>"",+AD8+AF8,0) -> 3.293 | AH8: =IF(AD8<>"",_xlfn.XLOOKUP(AD8,'STD SAP'!AD:AD,'STD SAP'!W:W,"",1),"") -> 33 | AI8: =IF(AG8<>"",_xlfn.XLOOKUP(AG8,'STD SAP'!AD:AD,'STD SAP'!W:W,"",1),"") -> 34 | AJ8: 2.2 | AL8: =F8-P8-Q8 -> 1550 | AV8: =IF(AO8<>"",AO8+AQ8+AS8+AU8,0) -> 0 | AW8: =E8+AX8 -> 46148 | AX8: =IF(BB8<=AG8,AB8,BC8+AB8-AH8) -> 37 | AY8: =AW8-TODAY() -> -147 | AZ8: =S8+AV8-AE8 -> 5000 | BA8: =ROUND(AZ8/Y8,3) -> 0.3 | BB8: =BA8+AD8 -> 3.293 | BC8: =_xlfn.XLOOKUP(BB8,'STD SAP'!AD:AD,'STD SAP'!W:W,"",1) -> 34 | BD8: SIDOARJO
A9: 7 | B9: 1000007 | C9: JG01-Silvy 1 S.3 (RCI, Terima Pakan, Seting Pakan) | D9: =17200*1.01 -> 17372 | E9: 46153 | F9: =CEILING(_xlfn.XLOOKUP(AJ9,'STD SAP'!X:X,'STD SAP'!AD:AD)*D9,50) -> 58550 | H9: =IF(G9<>"",G9-E9,0) -> 0 | J9: =IF(E9<>"",D9-I9,"") -> 17372 | L9: =IF(K9<>"",R9/K9/J9,"") | M9: =IF(L9<>"",L9-_xlfn.XLOOKUP(K9,'STD SAP'!X:X,'STD SAP'!AA:AA),"") | N9: =IF(R9<>"",ROUND(R9/D9,3),0) -> 0 | O9: =IF(S9<>"",ROUND((P9+Q9)/D9,3),0) -> 0.288 | P9: 5000 | S9: =IF(SUM(P9:Q9)<>0,+P9+Q9-R9,0) -> 5000 | T9: =IF(E9<>"",IF(E9<TODAY(),TODAY()-E9,0),"") -> 142 | Y9: =IF(D9<>"",J9-V9-X9,"") -> 17372 | Z9: =IF( OR(MAX(U9,W9)<G9, COUNTA(U9,W9)=0), H9, MAX(U9,W9)-E9 ) -> 0 | AA9: =IF(E9<>"",E9+AB9,"") -> 46162 | AB9: =IF(AG9<=AD9,Z9,AI9-AH9+Z9) -> 9 | AC9: =IF(E9<>"",AA9-TODAY(),"") -> -133 | AD9: =IF(OR(U9="",U9<=G9),N9,_xlfn.XLOOKUP(Z9-H9+_xlfn.XLOOKUP(N9,'STD SAP'!AD:AD,'STD SAP'!W:W,"",1),'STD SAP'!W:W,'STD SAP'!AD:AD)) -> 0 | AE9: =IF(Y9<>"",MIN(CEILING(Y9*(AD9-N9),50),S9),0) -> 0 | AF9: =IF(S9<>"",ROUND((S9-AE9)/Y9,3),"") -> 0.288 | AG9: =IF(AF9<>"",+AD9+AF9,0) -> 0.288 | AH9: =IF(AD9<>"",_xlfn.XLOOKUP(AD9,'STD SAP'!AD:AD,'STD SAP'!W:W,"",1),"") -> 0 | AI9: =IF(AG9<>"",_xlfn.XLOOKUP(AG9,'STD SAP'!AD:AD,'STD SAP'!W:W,"",1),"") -> 9 | AJ9: 2.2 | AL9: =F9-P9-Q9 -> 53550 | AM9: 46149 | AN9: GF 511 SUPER | AO9: 5000 | AV9: =IF(AO9<>"",AO9+AQ9+AS9+AU9,0) -> 5000 | AW9: =E9+AX9 -> 46176 | AX9: =IF(BB9<=AG9,AB9,BC9+AB9-AH9) -> 23 | AY9: =AW9-TODAY() -> -119 | AZ9: =S9+AV9-AE9 -> 10000 | BA9: =ROUND(AZ9/Y9,3) -> 0.576 | BB9: =BA9+AD9 -> 0.576 | BC9: =_xlfn.XLOOKUP(BB9,'STD SAP'!AD:AD,'STD SAP'!W:W,"",1) -> 14 | BD9: SIDOARJO
A10: 8 | B10: 1000008 | C10: JG02-Jeane 1 S.3 (RCI, Terima Pakan, Tanpa Seting Pakan) | D10: =17200*1.01 -> 17372 | E10: 46153 | F10: =CEILING(_xlfn.XLOOKUP(AJ10,'STD SAP'!X:X,'STD SAP'!AD:AD)*D10,50) -> 58550 | H10: =IF(G10<>"",G10-E10,0) -> 0 | J10: =IF(E10<>"",D10-I10,"") -> 17372 | L10: =IF(K10<>"",R10/K10/J10,"") | M10: =IF(L10<>"",L10-_xlfn.XLOOKUP(K10,'STD SAP'!X:X,'STD SAP'!AA:AA),"") | N10: =IF(R10<>"",ROUND(R10/D10,3),0) -> 0 | O10: =IF(S10<>"",ROUND((P10+Q10)/D10,3),0) -> 0.288 | P10: 5000 | S10: =IF(SUM(P10:Q10)<>0,+P10+Q10-R10,0) -> 5000 | T10: =IF(E10<>"",IF(E10<TODAY(),TODAY()-E10,0),"") -> 142 | Y10: =IF(D10<>"",J10-V10-X10,"") -> 17372 | Z10: =IF( OR(MAX(U10,W10)<G10, COUNTA(U10,W10)=0), H10, MAX(U10,W10)-E10 ) -> 0 | AA10: =IF(E10<>"",E10+AB10,"") -> 46162 | AB10: =IF(AG10<=AD10,Z10,AI10-AH10+Z10) -> 9 | AC10: =IF(E10<>"",AA10-TODAY(),"") -> -133 | AD10: =IF(OR(U10="",U10<=G10),N10,_xlfn.XLOOKUP(Z10-H10+_xlfn.XLOOKUP(N10,'STD SAP'!AD:AD,'STD SAP'!W:W,"",1),'STD SAP'!W:W,'STD SAP'!AD:AD)) -> 0 | AE10: =IF(Y10<>"",MIN(CEILING(Y10*(AD10-N10),50),S10),0) -> 0 | AF10: =IF(S10<>"",ROUND((S10-AE10)/Y10,3),"") -> 0.288 | AG10: =IF(AF10<>"",+AD10+AF10,0) -> 0.288 | AH10: =IF(AD10<>"",_xlfn.XLOOKUP(AD10,'STD SAP'!AD:AD,'STD SAP'!W:W,"",1),"") -> 0 | AI10: =IF(AG10<>"",_xlfn.XLOOKUP(AG10,'STD SAP'!AD:AD,'STD SAP'!W:W,"",1),"") -> 9 | AJ10: 2.2 | AL10: =F10-P10-Q10 -> 53550 | AV10: =IF(AO10<>"",AO10+AQ10+AS10+AU10,0) -> 0 | AW10: =E10+AX10 -> 46162 | AX10: =IF(BB10<=AG10,AB10,BC10+AB10-AH10) -> 9 | AY10: =AW10-TODAY() -> -133 | AZ10: =S10+AV10-AE10 -> 5000 | BA10: =ROUND(AZ10/Y10,3) -> 0.288 | BB10: =BA10+AD10 -> 0.288 | BC10: =_xlfn.XLOOKUP(BB10,'STD SAP'!AD:AD,'STD SAP'!W:W,"",1) -> 9 | BD10: SIDOARJO
